Workbook
Name ㄴㅇㅇ: #REF!

Sheet 신상품list
A1: 1 | B1: 2 | E1: 3 | F1: 4
B2: 구 분 | C2: 명칭 | D2: 상세 명칭 | E2: 물품 코드 | F2: 물품명 | G2: 생산처 | H2: 상품출시일 | I2: 채널전용 | J2: 1주차 (8.1~8.7) | K2: 2주차 (8.8~8.14) | L2: 3주차 (8.15~8.21) | M2: 4주차 (8.22~8.31) | N2: 1주차 (9.1~9.7) | O2: 2주차 (9.8~9.14) | P2: 3주차 (9.15~9.21) | Q2: 4주차 (9.22~9.30) | R2: 1주차 (10.1~10.7) | S2: 2주차 (10.8~10.14) | T2: 3주차 (10.15~10.21) | U2: 4주차 (10.22~10.31)
B3: 판매사업 | C3: 새우볶음밥 | D3: 새우볶음밥 | E3: 8801448764026 | F3: 농협 파기름 새우볶음밥420g | G3: 한우물 | H3: 46034 | J3: 2181219 | K3: 2604880 | L3: 1732985 | M3: 3232277 | N3: 1568032 | O3: 1957438 | P3: 2592321 | Q3: 1665959 | R3: 1878090 | S3: 3459712
B4: 판매사업 | C4: 설선물세트 | D4: 선물세트 즉석밥 | E4: 8801448764958 | F4: (선물세트) 한국농협밥 백미 선물세트 (210g * 10개입) | G4: 시아스 | H4: 46037 | J4: 0 | K4: 0 | L4: 0 | M4: 0 | N4: 0 | O4: 0 | P4: 0 | Q4: 0 | R4: 0 | S4: 0
B5: 판매사업 | C5: 설선물세트 | D5: 선물세트 율무차 | E5: 8801448765092 | F5: 농협 국산 호두 율무차 80T(1,600g) | G5: 북안동농협 | H5: 46037 | J5: 0 | K5: 0 | L5: 24545 | M5: 154364 | N5: 583310 | O5: 1069093 | P5: 246982 | Q5: 0 | R5: 15864218 | S5: 92618
B6: 판매사업 | C6: 설선물세트 | D6: 선물세트 참들기름 | E6: 8801448765153 | F6: 농협 프리미엄 국산 참들기름 선물세트 | G6: 남면농협 | H6: 46037 | J6: 0 | K6: 0 | L6: 0 | M6: 0 | N6: 0 | O6: 1090909 | P6: 1718946 | Q6: 5279620 | R6: 763636 | S6: 0
B7: 판매사업 | C7: 설선물세트 | D7: 선물세트 쌀국수 | E7: 8801448764804 | F7: (선물세트) 농협 우리쌀 쌀국수 선물세트 6입 (멸치, 파곰탕, 짬뽕) | G7: 현농 | H7: 46037 | J7: 0 | K7: 0 | L7: 0 | M7: 0 | N7: 0 | O7: 0 | P7: 0 | Q7: 0 | R7: 0 | S7: 0
B8: 판매사업 | C8: 과채음료 | D8: 국산담은 사과 | E8: 8801448759626 | F8: 농협 국산담은 사과 100ml | G8: 자임 | H8: 46097 | J8: 71820 | K8: 64638 | L8: 50274 | M8: 91018546 | N8: 416291 | O8: 317275 | P8: 137002 | Q8: 35910 | R8: 189002 | S8: 118638
B9: 판매사업 | C9: 과채음료 | D9: 국산담은 포도 | E9: 8801448759633 | F9: 농협 국산담은 포도 100ml | G9: 자임 | H9: 46097 | J9: 0 | K9: 35910 | L9: 45364 | M9: 46545 | N9: 251264 | O9: 281365 | P9: 98820 | Q9: 71820 | R9: 99092 | S9: 333818
B10: 판매사업 | C10: 쌀시리얼 | D10: 쌀시리얼 | E10: 8801448768406 | F10: 농협 저당 쌀 시리얼280g | G10: 북전주농협 | H10: 46198 | J10: 3384110 | K10: 4013564 | L10: 4009839 | M10: 5678639 | N10: 2408258 | O10: 1335357 | P10: 1732748 | Q10: 1184918 | R10: 1209289 | S10: 974038
B11: 단순판매 | C11: (단순)냉면 | D11: (단순)물냉면 | E11: 8801074802161 | F11: 한성 평양 물냉면 s 900g | G11: 한성기업 | H11: 46164 | J11: 4620447 | K11: 3567849 | L11: 1335833 | M11: 1343829 | N11: 510000 | O11: 110000 | P11: 0 | Q11: 385000 | R11: 10000 | S11: 5000
B12: 단순판매 | C12: (단순)냉면 | D12: (단순)비빔냉면 | E12: 8801074802567 | F12: 한성 함흥 비빔냉면s 400g | G12: 한성기업 | H12: 46164 | J12: 2058704 | K12: 2286975 | L12: 1027236 | M12: 1079824 | N12: 370000 | O12: 80000 | P12: -40000 | Q12: 355000 | R12: 90000 | S12: 0
B13: 판매사업 | C13: 대외용두부 | D13: 대외 투컵두부 부침 | E13: TR282575 | F13: (대외)농협국산콩두부(부침용) 300g*2 | G13: 기린원당농협 | H13: 46174 | I13: 온라인 | J13: 0 | K13: 0 | L13: 0 | M13: 0 | N13: 0 | O13: 0 | P13: 0 | Q13: 2193920 | R13: 0 | S13: 0
B14: 판매사업 | C14: 대외용두부 | D14: 대외 투컵두부 부찌 | E14: TR282582 | F14: (대외) 농협국산콩두부 부침찌개겸용 300g*2 | G14: 기린원당농협 | H14: 46174 | I14: 온라인 | J14: 0 | K14: 0 | L14: 0 | M14: 0 | N14: 0 | O14: 0 | P14: 0 | Q14: 1552800 | R14: 0 | S14: 0
B15: 단순판매 | C15: (단순)깐양파 | D15: (단순)깐양파 | E15: 8801448171077 | F15: 깐양파 450g | G15: 농협안성물류 | H15: 46181 | J15: 0 | K15: 0 | L15: 0 | M15: 0 | N15: 0 | O15: 0 | P15: 0 | Q15: 0 | R15: 0 | S15: 0
B16: 판매사업 | C16: 전통식혜 | D16: 전통식혜 | E16: 8801448768673 | F16: 농협 식혜 眞 1.5L PET | G16: 동밀양농협 | H16: 46204 | J16: 4084363 | K16: 2877939 | L16: 612115 | M16: 6152396 | N16: 6542910 | O16: 17903304 | P16: 43628245 | Q16: 12695388 | R16: 1518449 | S16: 2820788
B17: 판매사업 | C17: 대외용김치 | D17: 대외 포기 8kg | E17: 8801448767522 | F17: 한국농협김치 우리땅 포기김치 8kg | G17: 한국농협김치조합공동사업 충북지사 | H17: 46204 | J17: 0 | K17: 0 | L17: 0 | M17: 0 | N17: 0 | O17: 0 | P17: 0 | Q17: 1384816 | R17: 0 | S17: 0
B18: 판매사업 | C18: 대외용김치 | D18: 대외 포기 5kg | E18: 8801448767539 | F18: 한국농협김치 우리땅 포기김치 5kg | G18: 한국농협김치조합공동사업 충북지사 | H18: 46204 | J18: 0 | K18: 0 | L18: 0 | M18: 0 | N18: 0 | O18: 0 | P18: 0 | Q18: 1024864 | R18: 0 | S18: 0
B19: 판매사업 | C19: 대외용김치 | D19: 대외 열무김치 | E19: 8801448767546 | F19: 한국농협김치 열무김치 900g | G19: 한국농협김치조합공동사업법인 전남 | H19: 46204 | J19: 0 | K19: 0 | L19: 0 | M19: 0 | N19: 0 | O19: 0 | P19: 0 | Q19: 446900 | R19: 0 | S19: 0
B20: 판매사업 | C20: 대외용김치 | D20: 대외 총각김치 | E20: 8801448767553 | F20: 한국농협김치 총각김치 900g | G20: 한국농협김치조합공동사업법인 전남 | H20: 46204 | J20: 0 | K20: 0 | L20: 0 | M20: 0 | N20: 0 | O20: 0 | P20: 0 | Q20: 995160 | R20: 0 | S20: 0
B21: 판매사업 | C21: 대외용김치 | D21: 대외 갓김치 | E21: 8801448767591 | F21: 한국농협김치 갓김치 900g | G21: 한국농협김치조합공동사업법인 전남 | H21: 46204 | J21: 0 | K21: 0 | L21: 0 | M21: 0 | N21: 0 | O21: 0 | P21: 0 | Q21: 456540 | R21: 0 | S21: 0
B22: 판매사업 | C22: 매실청 | D22: 매실청 | E22: 8801448769588 | F22: 농협 발효 매실청 510g | G22: 티디바인 | H22: 46266 | J22: 0 | K22: 0 | L22: 0 | M22: 0 | N22: 1723892 | O22: 96809 | P22: 0 | Q22: 76910 | R22: 499915 | S22: 692188
B23: 단순판매 | C23: (단순)스틱새우젓 | D23: (단순)스틱새우젓 | E23: 8809403761288 | F23: 한숟갈 새우젓 100g(20g*5포) | G23: 서해글로벌 | H23: 46217 | J23: 24546 | K23: 7364 | L23: 98183 | M23: 0 | N23: 73637 | O23: 24546 | P23: 61365 | Q23: 24546 | R23: 24546 | S23: 0
B24: 단순판매 | C24: (단순)황홀태 | D24: (단순)황홀태 | E24: 8809090186722 | F24: 황홀태 스탠드 60g | G24: 선해수산 | H24: 46217 | J24: 463640 | K24: 1219370 | L24: 115910 | M24: 97364 | N24: 395729 | O24: 55747 | P24: 557456 | Q24: 159274 | R24: 37092 | S24: 146201
B25: 판매사업 | C25: 5무오리훈제 | D25: 5무오리훈제 | E25: 8801448775688 | F25: 농협 5무 훈제오리 바비큐 슬라이스400g | G25: 일영이푸드 | H25: 46237 | J25: 2053278 | K25: 20497066 | L25: 24926461 | M25: 60399057 | N25: 63238954 | O25: 50745889 | P25: 50567436 | Q25: 34304045 | R25: 38907168 | S25: 47868010
B26: 판매사업 | C26: 통통만두 | D26: 통통김치교자 | E26: 8801448773585 | F26: 농협 통통 김치교자 805g | G26: 엄지식품 | H26: 46244 | J26: 0 | K26: 0 | L26: 486768 | M26: 790117 | N26: 573923 | O26: 1083723 | P26: 936512 | Q26: 684501 | R26: 596514 | S26: 1893583
... B35: 단순판매 | C35: (단순)과일즙 | D35: (단순)도라지배즙 | E35: 8809114981425 | F35: (특판) 나주배원예농협 도라지배즙 | G35: 나주배 원예농업협동조합 | H35: 46254 | J35: 0 | K35: 0 | L35: 0 | M35: 98040000 | N35: 0 | O35: 0 | P35: 0 | Q35: 0 | R35: 0 | S35: 0
B36: 판매사업 | C36: 임실요거트 | D36: 요거트 플레인 | E36: 8803459000346 | F36: 농협 진짜요 플레인 500ml (임실) | G36: 임실치즈농협 | H36: 46258 | J36: 0 | N36: 2267459 | O36: 3105079 | P36: 4108567 | Q36: 2447814 | R36: 1337095 | S36: 1887238
B37: 판매사업 | C37: 임실요거트 | D37: 요거트 블루베리 | E37: 8803459001008 | F37: 농협 진짜요 블루베리 500ml (임실) | G37: 임실치즈농협 | H37: 46258 | J37: 0 | N37: 2682474 | O37: 3546498 | P37: 3746405 | Q37: 2969960 | R37: 1983009 | S37: 2717265
B38: 단순판매 | C38: (단순)골뱅이 | D38: (단순)골뱅이1 | E38: 임시 | F38: 골뱅이1 | G38: 화남코퍼레이션 | H38: 46321 | J38: 0
B39: 단순판매 | C39: (단순)골뱅이 | D39: (단순)골뱅이2 | E39: 임시 | F39: 골뱅이2 | G39: 화남코퍼레이션 | H39: 46321 | J39: 0
B40: 판매사업 | C40: 크리스피롤 딸기 | D40: 크리스피롤 딸기(대) | E40: 8801448776753 | F40: 농협 크리스피롤 21곡 딸기맛 370g | G40: 북안동농협 | H40: 46302 | J40: 0 | N40: 0 | O40: 0 | P40: 0 | Q40: 0 | R40: 0 | S40: 81182
B41: 판매사업 | C41: 크리스피롤 딸기 | D41: 크리스피롤 딸기(소) | E41: 8801448776760 | F41: 농협 크리스피롤 21곡 딸기맛 160g | G41: 북안동농협 | H41: 46302 | N41: 0 | O41: 0 | P41: 0 | Q41: 0 | R41: 0 | S41: 177091
B42: 판매사업 | C42: 감자옹심이 | D42: 감자옹심이 | E42: 8801448776562 | F42: 농협 감자옹심이 700g | G42: 미담라이스 | H42: 46309 | J42: 0 | N42: 0 | O42: 0 | P42: 0 | Q42: 0 | R42: 0 | S42: 547094
B43: 판매사업 | C43: 네컵연두부 | D43: 네컵연두부 | E43: 8801448776739 | F43: 농협 국산콩 네컵연두부 360g | G43: 맑은물에 | H43: 46318 | N43: 0 | O43: 0 | P43: 0 | Q43: 0 | R43: 0 | S43: 0
B44: 단순판매 | C44: 꾸이맨 | D44: 꾸이맨 점보 | E44: 8809081260097 | F44: 꼬마꾸이맨 점보 250g | G44: 나베가 | H44: 46321 | J44: 0 | N44: 0 | O44: 0 | P44: 0 | Q44: 0 | R44: 0 | S44: 0
B45: 단순판매 | C45: 꾸이맨 | D45: 꾸이맨 벌크 | E45: 8809081260110 | F45: 꾸이맨23g*10EA 벌크 | G45: 나베가 | H45: 46321 | J45: 0 | N45: 0 | O45: 0 | P45: 0 | Q45: 0 | R45: 0 | S45: 0
B46: 단순판매 | C46: 꾸이맨 | D46: 꼬마꾸이맨 | E46: 8809081260295 | F46: 꼬마꾸이맨50g | G46: 나베가 | H46: 46321 | J46: 0 | N46: 0 | O46: 0 | P46: 0 | Q46: 0 | R46: 0 | S46: 390275
B47: 단순판매 | C47: 핫도그 | D47: 핫도그 | E47: 임시 | F47: 핫도그 | G47: 진부농협 | H47: 46321
B48: 판매사업 | C48: 찹쌀떡 | D48: 찹쌀떡 | E48: 임시 | F48: 저당찹쌀떡 | G48: 정남농협 | H48: 46318
...

Sheet 매출원천
A1: 품번 | B1: 거래처(중) | C1: 1월 | D1: 2월 | E1: 3월 | F1: 4월 | G1: 5월 | H1: 6월 | I1: 7월 | J1: 8월 | K1: 9월 | L1: 10월 | M1: 11월 | N1: 12월
A2: 8801074802161 | B2: 계통대리점 | C2: 0 | D2: 0 | E2: 0 | F2: 0 | G2: 820218 | H2: 28405075 | I2: 25212200 | J2: 10897716 | K2: 1131382 | L2: 35000 | M2: 0 | N2: 0
A3: 8801074802567 | B3: 계통대리점 | C3: 0 | D3: 0 | E3: 0 | F3: 0 | G3: 797700 | H3: 24417417 | I3: 16670406 | J3: 6688515 | K3: 847829 | L3: 90000 | M3: 0 | N3: 0
A4: 8801448171077 | B4: 특판 | C4: 0 | D4: 0 | E4: 0 | F4: 0 | G4: 0 | H4: 7600000 | I4: 0 | J4: 0 | K4: 0 | L4: 0 | M4: 0 | N4: 0
A5: 8801448759626 | B5: TM | C5: 0 | D5: 0 | E5: 0 | F5: 0 | G5: 0 | H5: 0 | I5: 8202242 | J5: 10944900 | K5: 668700 | L5: 0 | M5: 0 | N5: 0
A6: 8801448759626 | B6: 계통대리점 | C6: 0 | D6: 0 | E6: 0 | F6: 0 | G6: 0 | H6: 619108 | I6: 1500055 | J6: 222642 | K6: 313369 | L6: 289551 | M6: 0 | N6: 0
A7: 8801448759626 | B7: 시판대리점 | C7: 0 | D7: 0 | E7: 0 | F7: 1282273 | G7: 3226364 | H7: 270000 | I7: 189000 | J7: 27000 | K7: 108000 | L7: 54000 | M7: 0 | N7: 0
A8: 8801448759626 | B8: 온라인 | C8: 0 | D8: 0 | E8: 0 | F8: 0 | G8: 0 | H8: 0 | I8: 271482 | J8: 88591 | K8: 1009691 | L8: 0 | M8: 0 | N8: 0
A9: 8801448759626 | B9: 유통(대외판매) | C9: 0 | D9: 0 | E9: 4446000 | F9: 0 | G9: 0 | H9: 0 | I9: 0 | J9: 0 | K9: 0 | L9: 0 | M9: 0 | N9: 0
A10: 8801448759626 | B10: 특판 | C10: 0 | D10: 0 | E10: 0 | F10: 0 | G10: 21818 | H10: 82228 | I10: 0 | J10: 90955636 | K10: 393182 | L10: 35909 | M10: 0 | N10: 0
A11: 8801448759626 | B11: 홈쇼핑 | C11: 0 | D11: 0 | E11: 0 | F11: 0 | G11: 0 | H11: 250182 | I11: 0 | J11: 398727 | K11: 0 | L11: 0 | M11: 0 | N11: 0
A12: 8801448759633 | B12: TM | C12: 0 | D12: 0 | E12: 0 | F12: 0 | G12: 0 | H12: 0 | I12: 738292 | J12: 9164700 | K12: 19887300 | L12: 0 | M12: 0 | N12: 0
A13: 8801448759633 | B13: 계통대리점 | C13: 0 | D13: 0 | E13: 0 | F13: 0 | G13: 0 | H13: 578698 | I13: 1100151 | J13: 92592 | K13: 253642 | L13: 110002 | M13: 0 | N13: 0
... A92: 8809081260295 | B92: 계통대리점 | C92: 0 | D92: 0 | E92: 0 | F92: 0 | G92: 0 | H92: 0 | I92: 0 | J92: 0 | K92: 0 | L92: 523258 | M92: 0 | N92: 0
A93: 출처: 월별 상품별 거래처분류별 매출실적_nhfood_20261019_2026.xlsx (업로드 파일, 2026-10-19). 신상품list 물품코드 해당 행만 추출해 품번×거래처(중)별 합산(거래처 미기재분은 '(미분류)'), 91행, 단위: 원. 10월은 10/19까지 부분실적. 2026-10-19 꾸이맨 코드 업데이트 반영.

Sheet 26년 신상품 월별매출
A1: 2026년 신상품 월별 매출액 및 10~12월 예상 (단위: 원)
A2: ※ 실적은 매출원천(10/19 기준) 집계, 10월 실적은 부분실적. 채널 조건 품목은 해당 거래처(중) 매출만 집계. Z~AC열(파란 글씨)로 품목별 예측 조정: 11~12월 기준 빈칸=최고월, 월평균=1~9월 매출발생월 평균, 10월=10월 예상치. 반영률 빈칸=100%
A3: 예측 가정
A4: 10월 예상 배수 (10월 실적 × 배수) | D4: 2
A5: 신상품 월 예상매출 (출시월부터) | D5: 10000000
A6: 신상품 기준 출시일 (이 날짜 이후 출시) | D6: 46296
A7: 스팟 판정: 매출발생 월수 이하 | D7: 2
A8: 실적 기준월 | D8: 46296
V9: =DATE(YEAR($D$8),MONTH($D$8),1) | W9: =EDATE(V9,1) | X9: =EDATE(W9,1)
A10: 구분 | B10: 명칭 | C10: 상세 명칭 | D10: 물품 코드 | E10: 물품명 | F10: 상품출시일 | G10: 채널 조건 | H10: 1월 실적 | I10: 2월 실적 | J10: 3월 실적 | K10: 4월 실적 | L10: 5월 실적 | M10: 6월 실적 | N10: 7월 실적 | O10: 8월 실적 | P10: 9월 실적 | Q10: 10월 실적 | R10: 매출발생 월수 | S10: 출시후 경과월수 | T10: 최고월 매출 | U10: 예측 유형 | V10: 10월 예상 | W10: 11월 예상 | X10: 12월 예상 | Y10: 연간 예상 | Z10: 유형 지정 | AA10: 11~12월 기준 | AB10: 10월 반영률 | AC10: 11월 반영률
A11: =신상품list!B3 | B11: =신상품list!C3 | C11: =신상품list!D3 | D11: =신상품list!E3&"" | E11: =신상품list!F3 | F11: =신상품list!H3 | G11: =IF(신상품list!I3="","전체",신상품list!I3) | H11: =SUMIFS(매출원천!C:C,매출원천!$A:$A,$D11,매출원천!$B:$B,IF($G11="전체","*",$G11)) | I11: =SUMIFS(매출원천!D:D,매출원천!$A:$A,$D11,매출원천!$B:$B,IF($G11="전체","*",$G11)) | J11: =SUMIFS(매출원천!E:E,매출원천!$A:$A,$D11,매출원천!$B:$B,IF($G11="전체","*",$G11)) | K11: =SUMIFS(매출원천!F:F,매출원천!$A:$A,$D11,매출원천!$B:$B,IF($G11="전체","*",$G11)) | L11: =SUMIFS(매출원천!G:G,매출원천!$A:$A,$D11,매출원천!$B:$B,IF($G11="전체","*",$G11)) | M11: =SUMIFS(매출원천!H:H,매출원천!$A:$A,$D11,매출원천!$B:$B,IF($G11="전체","*",$G11)) | N11: =SUMIFS(매출원천!I:I,매출원천!$A:$A,$D11,매출원천!$B:$B,IF($G11="전체","*",$G11)) | O11: =SUMIFS(매출원천!J:J,매출원천!$A:$A,$D11,매출원천!$B:$B,IF($G11="전체","*",$G11)) | P11: =SUMIFS(매출원천!K:K,매출원천!$A:$A,$D11,매출원천!$B:$B,IF($G11="전체","*",$G11)) | Q11: =SUMIFS(매출원천!L:L,매출원천!$A:$A,$D11,매출원천!$B:$B,IF($G11="전체","*",$G11)) | R11: =COUNTIF(H11:Q11,">0") | S11: =IF($F11="",0,(YEAR($D$8)-YEAR($F11))*12+MONTH($D$8)-MONTH($F11)+1) | T11: =MAX(H11:Q11) | U11: =IF($Z11<>"",$Z11,IF($F11>=$D$6,"신상품",IF(AND($R11<=$D$7,$S11>$D$7),"스팟","기존"))) | V11: =IF($U11="신상품",IF($F11<=EOMONTH(V$9,0),$D$5,0),IF($U11="스팟",$Q11,$Q11*$D$4))*IF($AB11="",1,$AB11) | W11: =IF($U11="신상품",IF($F11<=EOMONTH(W$9,0),$D$5,0),IF($U11="스팟",0,IF($AA11="월평균",AVERAGEIF($H11:$P11,">0"),IF($AA11="9월",$P11,IF($AA11="10월",$V11,$T11)))))*IF($AC11="",1,$AC11) | X11: =IF($U11="신상품",IF($F11<=EOMONTH(X$9,0),$D$5,0),IF($U11="스팟",0,IF($AA11="월평균",AVERAGEIF($H11:$P11,">0"),IF($AA11="9월",$P11,IF($AA11="10월",$V11,$T11))))) | Y11: =SUM(H11:P11)+SUM(V11:X11)
A12: =신상품list!B4 | B12: =신상품list!C4 | C12: =신상품list!D4 | D12: =신상품list!E4&"" | E12: =신상품list!F4 | F12: =신상품list!H4 | G12: =IF(신상품list!I4="","전체",신상품list!I4) | H12: =SUMIFS(매출원천!C:C,매출원천!$A:$A,$D12,매출원천!$B:$B,IF($G12="전체","*",$G12)) | I12: =SUMIFS(매출원천!D:D,매출원천!$A:$A,$D12,매출원천!$B:$B,IF($G12="전체","*",$G12)) | J12: =SUMIFS(매출원천!E:E,매출원천!$A:$A,$D12,매출원천!$B:$B,IF($G12="전체","*",$G12)) | K12: =SUMIFS(매출원천!F:F,매출원천!$A:$A,$D12,매출원천!$B:$B,IF($G12="전체","*",$G12)) | L12: =SUMIFS(매출원천!G:G,매출원천!$A:$A,$D12,매출원천!$B:$B,IF($G12="전체","*",$G12)) | M12: =SUMIFS(매출원천!H:H,매출원천!$A:$A,$D12,매출원천!$B:$B,IF($G12="전체","*",$G12)) | N12: =SUMIFS(매출원천!I:I,매출원천!$A:$A,$D12,매출원천!$B:$B,IF($G12="전체","*",$G12)) | O12: =SUMIFS(매출원천!J:J,매출원천!$A:$A,$D12,매출원천!$B:$B,IF($G12="전체","*",$G12)) | P12: =SUMIFS(매출원천!K:K,매출원천!$A:$A,$D12,매출원천!$B:$B,IF($G12="전체","*",$G12)) | Q12: =SUMIFS(매출원천!L:L,매출원천!$A:$A,$D12,매출원천!$B:$B,IF($G12="전체","*",$G12)) | R12: =COUNTIF(H12:Q12,">0") | S12: =IF($F12="",0,(YEAR($D$8)-YEAR($F12))*12+MONTH($D$8)-MONTH($F12)+1) | T12: =MAX(H12:Q12) | U12: =IF($Z12<>"",$Z12,IF($F12>=$D$6,"신상품",IF(AND($R12<=$D$7,$S12>$D$7),"스팟","기존"))) | V12: =IF($U12="신상품",IF($F12<=EOMONTH(V$9,0),$D$5,0),IF($U12="스팟",$Q12,$Q12*$D$4))*IF($AB12="",1,$AB12) | W12: =IF($U12="신상품",IF($F12<=EOMONTH(W$9,0),$D$5,0),IF($U12="스팟",0,IF($AA12="월평균",AVERAGEIF($H12:$P12,">0"),IF($AA12="9월",$P12,IF($AA12="10월",$V12,$T12)))))*IF($AC12="",1,$AC12) | X12: =IF($U12="신상품",IF($F12<=EOMONTH(X$9,0),$D$5,0),IF($U12="스팟",0,IF($AA12="월평균",AVERAGEIF($H12:$P12,">0"),IF($AA12="9월",$P12,IF($AA12="10월",$V12,$T12))))) | Y12: =SUM(H12:P12)+SUM(V12:X12)
A13: =신상품list!B5 | B13: =신상품list!C5 | C13: =신상품list!D5 | D13: =신상품list!E5&"" | E13: =신상품list!F5 | F13: =신상품list!H5 | G13: =IF(신상품list!I5="","전체",신상품list!I5) | H13: =SUMIFS(매출원천!C:C,매출원천!$A:$A,$D13,매출원천!$B:$B,IF($G13="전체","*",$G13)) | I13: =SUMIFS(매출원천!D:D,매출원천!$A:$A,$D13,매출원천!$B:$B,IF($G13="전체","*",$G13)) | J13: =SUMIFS(매출원천!E:E,매출원천!$A:$A,$D13,매출원천!$B:$B,IF($G13="전체","*",$G13)) | K13: =SUMIFS(매출원천!F:F,매출원천!$A:$A,$D13,매출원천!$B:$B,IF($G13="전체","*",$G13)) | L13: =SUMIFS(매출원천!G:G,매출원천!$A:$A,$D13,매출원천!$B:$B,IF($G13="전체","*",$G13)) | M13: =SUMIFS(매출원천!H:H,매출원천!$A:$A,$D13,매출원천!$B:$B,IF($G13="전체","*",$G13)) | N13: =SUMIFS(매출원천!I:I,매출원천!$A:$A,$D13,매출원천!$B:$B,IF($G13="전체","*",$G13)) | O13: =SUMIFS(매출원천!J:J,매출원천!$A:$A,$D13,매출원천!$B:$B,IF($G13="전체","*",$G13)) | P13: =SUMIFS(매출원천!K:K,매출원천!$A:$A,$D13,매출원천!$B:$B,IF($G13="전체","*",$G13)) | Q13: =SUMIFS(매출원천!L:L,매출원천!$A:$A,$D13,매출원천!$B:$B,IF($G13="전체","*",$G13)) | R13: =COUNTIF(H13:Q13,">0") | S13: =IF($F13="",0,(YEAR($D$8)-YEAR($F13))*12+MONTH($D$8)-MONTH($F13)+1) | T13: =MAX(H13:Q13) | U13: =IF($Z13<>"",$Z13,IF($F13>=$D$6,"신상품",IF(AND($R13<=$D$7,$S13>$D$7),"스팟","기존"))) | V13: =IF($U13="신상품",IF($F13<=EOMONTH(V$9,0),$D$5,0),IF($U13="스팟",$Q13,$Q13*$D$4))*IF($AB13="",1,$AB13) | W13: =IF($U13="신상품",IF($F13<=EOMONTH(W$9,0),$D$5,0),IF($U13="스팟",0,IF($AA13="월평균",AVERAGEIF($H13:$P13,">0"),IF($AA13="9월",$P13,IF($AA13="10월",$V13,$T13)))))*IF($AC13="",1,$AC13) | X13: =IF($U13="신상품",IF($F13<=EOMONTH(X$9,0),$D$5,0),IF($U13="스팟",0,IF($AA13="월평균",AVERAGEIF($H13:$P13,">0"),IF($AA13="9월",$P13,IF($AA13="10월",$V13,$T13))))) | Y13: =SUM(H13:P13)+SUM(V13:X13)
A14: =신상품list!B6 | B14: =신상품list!C6 | C14: =신상품list!D6 | D14: =신상품list!E6&"" | E14: =신상품list!F6 | F14: =신상품list!H6 | G14: =IF(신상품list!I6="","전체",신상품list!I6) | H14: =SUMIFS(매출원천!C:C,매출원천!$A:$A,$D14,매출원천!$B:$B,IF($G14="전체","*",$G14)) | I14: =SUMIFS(매출원천!D:D,매출원천!$A:$A,$D14,매출원천!$B:$B,IF($G14="전체","*",$G14)) | J14: =SUMIFS(매출원천!E:E,매출원천!$A:$A,$D14,매출원천!$B:$B,IF($G14="전체","*",$G14)) | K14: =SUMIFS(매출원천!F:F,매출원천!$A:$A,$D14,매출원천!$B:$B,IF($G14="전체","*",$G14)) | L14: =SUMIFS(매출원천!G:G,매출원천!$A:$A,$D14,매출원천!$B:$B,IF($G14="전체","*",$G14)) | M14: =SUMIFS(매출원천!H:H,매출원천!$A:$A,$D14,매출원천!$B:$B,IF($G14="전체","*",$G14)) | N14: =SUMIFS(매출원천!I:I,매출원천!$A:$A,$D14,매출원천!$B:$B,IF($G14="전체","*",$G14)) | O14: =SUMIFS(매출원천!J:J,매출원천!$A:$A,$D14,매출원천!$B:$B,IF($G14="전체","*",$G14)) | P14: =SUMIFS(매출원천!K:K,매출원천!$A:$A,$D14,매출원천!$B:$B,IF($G14="전체","*",$G14)) | Q14: =SUMIFS(매출원천!L:L,매출원천!$A:$A,$D14,매출원천!$B:$B,IF($G14="전체","*",$G14)) | R14: =COUNTIF(H14:Q14,">0") | S14: =IF($F14="",0,(YEAR($D$8)-YEAR($F14))*12+MONTH($D$8)-MONTH($F14)+1) | T14: =MAX(H14:Q14) | U14: =IF($Z14<>"",$Z14,IF($F14>=$D$6,"신상품",IF(AND($R14<=$D$7,$S14>$D$7),"스팟","기존"))) | V14: =IF($U14="신상품",IF($F14<=EOMONTH(V$9,0),$D$5,0),IF($U14="스팟",$Q14,$Q14*$D$4))*IF($AB14="",1,$AB14) | W14: =IF($U14="신상품",IF($F14<=EOMONTH(W$9,0),$D$5,0),IF($U14="스팟",0,IF($AA14="월평균",AVERAGEIF($H14:$P14,">0"),IF($AA14="9월",$P14,IF($AA14="10월",$V14,$T14)))))*IF($AC14="",1,$AC14) | X14: =IF($U14="신상품",IF($F14<=EOMONTH(X$9,0),$D$5,0),IF($U14="스팟",0,IF($AA14="월평균",AVERAGEIF($H14:$P14,">0"),IF($AA14="9월",$P14,IF($AA14="10월",$V14,$T14))))) | Y14: =SUM(H14:P14)+SUM(V14:X14)
A15: =신상품list!B7 | B15: =신상품list!C7 | C15: =신상품list!D7 | D15: =신상품list!E7&"" | E15: =신상품list!F7 | F15: =신상품list!H7 | G15: =IF(신상품list!I7="","전체",신상품list!I7) | H15: =SUMIFS(매출원천!C:C,매출원천!$A:$A,$D15,매출원천!$B:$B,IF($G15="전체","*",$G15)) | I15: =SUMIFS(매출원천!D:D,매출원천!$A:$A,$D15,매출원천!$B:$B,IF($G15="전체","*",$G15)) | J15: =SUMIFS(매출원천!E:E,매출원천!$A:$A,$D15,매출원천!$B:$B,IF($G15="전체","*",$G15)) | K15: =SUMIFS(매출원천!F:F,매출원천!$A:$A,$D15,매출원천!$B:$B,IF($G15="전체","*",$G15)) | L15: =SUMIFS(매출원천!G:G,매출원천!$A:$A,$D15,매출원천!$B:$B,IF($G15="전체","*",$G15)) | M15: =SUMIFS(매출원천!H:H,매출원천!$A:$A,$D15,매출원천!$B:$B,IF($G15="전체","*",$G15)) | N15: =SUMIFS(매출원천!I:I,매출원천!$A:$A,$D15,매출원천!$B:$B,IF($G15="전체","*",$G15)) | O15: =SUMIFS(매출원천!J:J,매출원천!$A:$A,$D15,매출원천!$B:$B,IF($G15="전체","*",$G15)) | P15: =SUMIFS(매출원천!K:K,매출원천!$A:$A,$D15,매출원천!$B:$B,IF($G15="전체","*",$G15)) | Q15: =SUMIFS(매출원천!L:L,매출원천!$A:$A,$D15,매출원천!$B:$B,IF($G15="전체","*",$G15)) | R15: =COUNTIF(H15:Q15,">0") | S15: =IF($F15="",0,(YEAR($D$8)-YEAR($F15))*12+MONTH($D$8)-MONTH($F15)+1) | T15: =MAX(H15:Q15) | U15: =IF($Z15<>"",$Z15,IF($F15>=$D$6,"신상품",IF(AND($R15<=$D$7,$S15>$D$7),"스팟","기존"))) | V15: =IF($U15="신상품",IF($F15<=EOMONTH(V$9,0),$D$5,0),IF($U15="스팟",$Q15,$Q15*$D$4))*IF($AB15="",1,$AB15) | W15: =IF($U15="신상품",IF($F15<=EOMONTH(W$9,0),$D$5,0),IF($U15="스팟",0,IF($AA15="월평균",AVERAGEIF($H15:$P15,">0"),IF($AA15="9월",$P15,IF($AA15="10월",$V15,$T15)))))*IF($AC15="",1,$AC15) | X15: =IF($U15="신상품",IF($F15<=EOMONTH(X$9,0),$D$5,0),IF($U15="스팟",0,IF($AA15="월평균",AVERAGEIF($H15:$P15,">0"),IF($AA15="9월",$P15,IF($AA15="10월",$V15,$T15))))) | Y15: =SUM(H15:P15)+SUM(V15:X15) | Z15: 스팟
A16: =신상품list!B8 | B16: =신상품list!C8 | C16: =신상품list!D8 | D16: =신상품list!E8&"" | E16: =신상품list!F8 | F16: =신상품list!H8 | G16: =IF(신상품list!I8="","전체",신상품list!I8) | H16: =SUMIFS(매출원천!C:C,매출원천!$A:$A,$D16,매출원천!$B:$B,IF($G16="전체","*",$G16)) | I16: =SUMIFS(매출원천!D:D,매출원천!$A:$A,$D16,매출원천!$B:$B,IF($G16="전체","*",$G16)) | J16: =SUMIFS(매출원천!E:E,매출원천!$A:$A,$D16,매출원천!$B:$B,IF($G16="전체","*",$G16)) | K16: =SUMIFS(매출원천!F:F,매출원천!$A:$A,$D16,매출원천!$B:$B,IF($G16="전체","*",$G16)) | L16: =SUMIFS(매출원천!G:G,매출원천!$A:$A,$D16,매출원천!$B:$B,IF($G16="전체","*",$G16)) | M16: =SUMIFS(매출원천!H:H,매출원천!$A:$A,$D16,매출원천!$B:$B,IF($G16="전체","*",$G16)) | N16: =SUMIFS(매출원천!I:I,매출원천!$A:$A,$D16,매출원천!$B:$B,IF($G16="전체","*",$G16)) | O16: =SUMIFS(매출원천!J:J,매출원천!$A:$A,$D16,매출원천!$B:$B,IF($G16="전체","*",$G16)) | P16: =SUMIFS(매출원천!K:K,매출원천!$A:$A,$D16,매출원천!$B:$B,IF($G16="전체","*",$G16)) | Q16: =SUMIFS(매출원천!L:L,매출원천!$A:$A,$D16,매출원천!$B:$B,IF($G16="전체","*",$G16)) | R16: =COUNTIF(H16:Q16,">0") | S16: =IF($F16="",0,(YEAR($D$8)-YEAR($F16))*12+MONTH($D$8)-MONTH($F16)+1) | T16: =MAX(H16:Q16) | U16: =IF($Z16<>"",$Z16,IF($F16>=$D$6,"신상품",IF(AND($R16<=$D$7,$S16>$D$7),"스팟","기존"))) | V16: =IF($U16="신상품",IF($F16<=EOMONTH(V$9,0),$D$5,0),IF($U16="스팟",$Q16,$Q16*$D$4))*IF($AB16="",1,$AB16) | W16: =IF($U16="신상품",IF($F16<=EOMONTH(W$9,0),$D$5,0),IF($U16="스팟",0,IF($AA16="월평균",AVERAGEIF($H16:$P16,">0"),IF($AA16="9월",$P16,IF($AA16="10월",$V16,$T16)))))*IF($AC16="",1,$AC16) | X16: =IF($U16="신상품",IF($F16<=EOMONTH(X$9,0),$D$5,0),IF($U16="스팟",0,IF($AA16="월평균",AVERAGEIF($H16:$P16,">0"),IF($AA16="9월",$P16,IF($AA16="10월",$V16,$T16))))) | Y16: =SUM(H16:P16)+SUM(V16:X16) | AA16: 월평균
A17: =신상품list!B9 | B17: =신상품list!C9 | C17: =신상품list!D9 | D17: =신상품list!E9&"" | E17: =신상품list!F9 | F17: =신상품list!H9 | G17: =IF(신상품list!I9="","전체",신상품list!I9) | H17: =SUMIFS(매출원천!C:C,매출원천!$A:$A,$D17,매출원천!$B:$B,IF($G17="전체","*",$G17)) | I17: =SUMIFS(매출원천!D:D,매출원천!$A:$A,$D17,매출원천!$B:$B,IF($G17="전체","*",$G17)) | J17: =SUMIFS(매출원천!E:E,매출원천!$A:$A,$D17,매출원천!$B:$B,IF($G17="전체","*",$G17)) | K17: =SUMIFS(매출원천!F:F,매출원천!$A:$A,$D17,매출원천!$B:$B,IF($G17="전체","*",$G17)) | L17: =SUMIFS(매출원천!G:G,매출원천!$A:$A,$D17,매출원천!$B:$B,IF($G17="전체","*",$G17)) | M17: =SUMIFS(매출원천!H:H,매출원천!$A:$A,$D17,매출원천!$B:$B,IF($G17="전체","*",$G17)) | N17: =SUMIFS(매출원천!I:I,매출원천!$A:$A,$D17,매출원천!$B:$B,IF($G17="전체","*",$G17)) | O17: =SUMIFS(매출원천!J:J,매출원천!$A:$A,$D17,매출원천!$B:$B,IF($G17="전체","*",$G17)) | P17: =SUMIFS(매출원천!K:K,매출원천!$A:$A,$D17,매출원천!$B:$B,IF($G17="전체","*",$G17)) | Q17: =SUMIFS(매출원천!L:L,매출원천!$A:$A,$D17,매출원천!$B:$B,IF($G17="전체","*",$G17)) | R17: =COUNTIF(H17:Q17,">0") | S17: =IF($F17="",0,(YEAR($D$8)-YEAR($F17))*12+MONTH($D$8)-MONTH($F17)+1) | T17: =MAX(H17:Q17) | U17: =IF($Z17<>"",$Z17,IF($F17>=$D$6,"신상품",IF(AND($R17<=$D$7,$S17>$D$7),"스팟","기존"))) | V17: =IF($U17="신상품",IF($F17<=EOMONTH(V$9,0),$D$5,0),IF($U17="스팟",$Q17,$Q17*$D$4))*IF($AB17="",1,$AB17) | W17: =IF($U17="신상품",IF($F17<=EOMONTH(W$9,0),$D$5,0),IF($U17="스팟",0,IF($AA17="월평균",AVERAGEIF($H17:$P17,">0"),IF($AA17="9월",$P17,IF($AA17="10월",$V17,$T17)))))*IF($AC17="",1,$AC17) | X17: =IF($U17="신상품",IF($F17<=EOMONTH(X$9,0),$D$5,0),IF($U17="스팟",0,IF($AA17="월평균",AVERAGEIF($H17:$P17,">0"),IF($AA17="9월",$P17,IF($AA17="10월",$V17,$T17))))) | Y17: =SUM(H17:P17)+SUM(V17:X17) | AA17: 월평균
A18: =신상품list!B10 | B18: =신상품list!C10 | C18: =신상품list!D10 | D18: =신상품list!E10&"" | E18: =신상품list!F10 | F18: =신상품list!H10 | G18: =IF(신상품list!I10="","전체",신상품list!I10) | H18: =SUMIFS(매출원천!C:C,매출원천!$A:$A,$D18,매출원천!$B:$B,IF($G18="전체","*",$G18)) | I18: =SUMIFS(매출원천!D:D,매출원천!$A:$A,$D18,매출원천!$B:$B,IF($G18="전체","*",$G18)) | J18: =SUMIFS(매출원천!E:E,매출원천!$A:$A,$D18,매출원천!$B:$B,IF($G18="전체","*",$G18)) | K18: =SUMIFS(매출원천!F:F,매출원천!$A:$A,$D18,매출원천!$B:$B,IF($G18="전체","*",$G18)) | L18: =SUMIFS(매출원천!G:G,매출원천!$A:$A,$D18,매출원천!$B:$B,IF($G18="전체","*",$G18)) | M18: =SUMIFS(매출원천!H:H,매출원천!$A:$A,$D18,매출원천!$B:$B,IF($G18="전체","*",$G18)) | N18: =SUMIFS(매출원천!I:I,매출원천!$A:$A,$D18,매출원천!$B:$B,IF($G18="전체","*",$G18)) | O18: =SUMIFS(매출원천!J:J,매출원천!$A:$A,$D18,매출원천!$B:$B,IF($G18="전체","*",$G18)) | P18: =SUMIFS(매출원천!K:K,매출원천!$A:$A,$D18,매출원천!$B:$B,IF($G18="전체","*",$G18)) | Q18: =SUMIFS(매출원천!L:L,매출원천!$A:$A,$D18,매출원천!$B:$B,IF($G18="전체","*",$G18)) | R18: =COUNTIF(H18:Q18,">0") | S18: =IF($F18="",0,(YEAR($D$8)-YEAR($F18))*12+MONTH($D$8)-MONTH($F18)+1) | T18: =MAX(H18:Q18) | U18: =IF($Z18<>"",$Z18,IF($F18>=$D$6,"신상품",IF(AND($R18<=$D$7,$S18>$D$7),"스팟","기존"))) | V18: =IF($U18="신상품",IF($F18<=EOMONTH(V$9,0),$D$5,0),IF($U18="스팟",$Q18,$Q18*$D$4))*IF($AB18="",1,$AB18) | W18: =IF($U18="신상품",IF($F18<=EOMONTH(W$9,0),$D$5,0),IF($U18="스팟",0,IF($AA18="월평균",AVERAGEIF($H18:$P18,">0"),IF($AA18="9월",$P18,IF($AA18="10월",$V18,$T18)))))*IF($AC18="",1,$AC18) | X18: =IF($U18="신상품",IF($F18<=EOMONTH(X$9,0),$D$5,0),IF($U18="스팟",0,IF($AA18="월평균",AVERAGEIF($H18:$P18,">0"),IF($AA18="9월",$P18,IF($AA18="10월",$V18,$T18))))) | Y18: =SUM(H18:P18)+SUM(V18:X18) | AA18: 9월
A19: =신상품list!B11 | B19: =신상품list!C11 | C19: =신상품list!D11 | D19: =신상품list!E11&"" | E19: =신상품list!F11 | F19: =신상품list!H11 | G19: =IF(신상품list!I11="","전체",신상품list!I11) | H19: =SUMIFS(매출원천!C:C,매출원천!$A:$A,$D19,매출원천!$B:$B,IF($G19="전체","*",$G19)) | I19: =SUMIFS(매출원천!D:D,매출원천!$A:$A,$D19,매출원천!$B:$B,IF($G19="전체","*",$G19)) | J19: =SUMIFS(매출원천!E:E,매출원천!$A:$A,$D19,매출원천!$B:$B,IF($G19="전체","*",$G19)) | K19: =SUMIFS(매출원천!F:F,매출원천!$A:$A,$D19,매출원천!$B:$B,IF($G19="전체","*",$G19)) | L19: =SUMIFS(매출원천!G:G,매출원천!$A:$A,$D19,매출원천!$B:$B,IF($G19="전체","*",$G19)) | M19: =SUMIFS(매출원천!H:H,매출원천!$A:$A,$D19,매출원천!$B:$B,IF($G19="전체","*",$G19)) | N19: =SUMIFS(매출원천!I:I,매출원천!$A:$A,$D19,매출원천!$B:$B,IF($G19="전체","*",$G19)) | O19: =SUMIFS(매출원천!J:J,매출원천!$A:$A,$D19,매출원천!$B:$B,IF($G19="전체","*",$G19)) | P19: =SUMIFS(매출원천!K:K,매출원천!$A:$A,$D19,매출원천!$B:$B,IF($G19="전체","*",$G19)) | Q19: =SUMIFS(매출원천!L:L,매출원천!$A:$A,$D19,매출원천!$B:$B,IF($G19="전체","*",$G19)) | R19: =COUNTIF(H19:Q19,">0") | S19: =IF($F19="",0,(YEAR($D$8)-YEAR($F19))*12+MONTH($D$8)-MONTH($F19)+1) | T19: =MAX(H19:Q19) | U19: =IF($Z19<>"",$Z19,IF($F19>=$D$6,"신상품",IF(AND($R19<=$D$7,$S19>$D$7),"스팟","기존"))) | V19: =IF($U19="신상품",IF($F19<=EOMONTH(V$9,0),$D$5,0),IF($U19="스팟",$Q19,$Q19*$D$4))*IF($AB19="",1,$AB19) | W19: =IF($U19="신상품",IF($F19<=EOMONTH(W$9,0),$D$5,0),IF($U19="스팟",0,IF($AA19="월평균",AVERAGEIF($H19:$P19,">0"),IF($AA19="9월",$P19,IF($AA19="10월",$V19,$T19)))))*IF($AC19="",1,$AC19) | X19: =IF($U19="신상품",IF($F19<=EOMONTH(X$9,0),$D$5,0),IF($U19="스팟",0,IF($AA19="월평균",AVERAGEIF($H19:$P19,">0"),IF($AA19="9월",$P19,IF($AA19="10월",$V19,$T19))))) | Y19: =SUM(H19:P19)+SUM(V19:X19) | AA19: 9월
A20: =신상품list!B12 | B20: =신상품list!C12 | C20: =신상품list!D12 | D20: =신상품list!E12&"" | E20: =신상품list!F12 | F20: =신상품list!H12 | G20: =IF(신상품list!I12="","전체",신상품list!I12) | H20: =SUMIFS(매출원천!C:C,매출원천!$A:$A,$D20,매출원천!$B:$B,IF($G20="전체","*",$G20)) | I20: =SUMIFS(매출원천!D:D,매출원천!$A:$A,$D20,매출원천!$B:$B,IF($G20="전체","*",$G20)) | J20: =SUMIFS(매출원천!E:E,매출원천!$A:$A,$D20,매출원천!$B:$B,IF($G20="전체","*",$G20)) | K20: =SUMIFS(매출원천!F:F,매출원천!$A:$A,$D20,매출원천!$B:$B,IF($G20="전체","*",$G20)) | L20: =SUMIFS(매출원천!G:G,매출원천!$A:$A,$D20,매출원천!$B:$B,IF($G20="전체","*",$G20)) | M20: =SUMIFS(매출원천!H:H,매출원천!$A:$A,$D20,매출원천!$B:$B,IF($G20="전체","*",$G20)) | N20: =SUMIFS(매출원천!I:I,매출원천!$A:$A,$D20,매출원천!$B:$B,IF($G20="전체","*",$G20)) | O20: =SUMIFS(매출원천!J:J,매출원천!$A:$A,$D20,매출원천!$B:$B,IF($G20="전체","*",$G20)) | P20: =SUMIFS(매출원천!K:K,매출원천!$A:$A,$D20,매출원천!$B:$B,IF($G20="전체","*",$G20)) | Q20: =SUMIFS(매출원천!L:L,매출원천!$A:$A,$D20,매출원천!$B:$B,IF($G20="전체","*",$G20)) | R20: =COUNTIF(H20:Q20,">0") | S20: =IF($F20="",0,(YEAR($D$8)-YEAR($F20))*12+MONTH($D$8)-MONTH($F20)+1) | T20: =MAX(H20:Q20) | U20: =IF($Z20<>"",$Z20,IF($F20>=$D$6,"신상품",IF(AND($R20<=$D$7,$S20>$D$7),"스팟","기존"))) | V20: =IF($U20="신상품",IF($F20<=EOMONTH(V$9,0),$D$5,0),IF($U20="스팟",$Q20,$Q20*$D$4))*IF($AB20="",1,$AB20) | W20: =IF($U20="신상품",IF($F20<=EOMONTH(W$9,0),$D$5,0),IF($U20="스팟",0,IF($AA20="월평균",AVERAGEIF($H20:$P20,">0"),IF($AA20="9월",$P20,IF($AA20="10월",$V20,$T20)))))*IF($AC20="",1,$AC20) | X20: =IF($U20="신상품",IF($F20<=EOMONTH(X$9,0),$D$5,0),IF($U20="스팟",0,IF($AA20="월평균",AVERAGEIF($H20:$P20,">0"),IF($AA20="9월",$P20,IF($AA20="10월",$V20,$T20))))) | Y20: =SUM(H20:P20)+SUM(V20:X20) | AA20: 9월
A21: =신상품list!B13 | B21: =신상품list!C13 | C21: =신상품list!D13 | D21: =신상품list!E13&"" | E21: =신상품list!F13 | F21: =신상품list!H13 | G21: =IF(신상품list!I13="","전체",신상품list!I13) | H21: =SUMIFS(매출원천!C:C,매출원천!$A:$A,$D21,매출원천!$B:$B,IF($G21="전체","*",$G21)) | I21: =SUMIFS(매출원천!D:D,매출원천!$A:$A,$D21,매출원천!$B:$B,IF($G21="전체","*",$G21)) | J21: =SUMIFS(매출원천!E:E,매출원천!$A:$A,$D21,매출원천!$B:$B,IF($G21="전체","*",$G21)) | K21: =SUMIFS(매출원천!F:F,매출원천!$A:$A,$D21,매출원천!$B:$B,IF($G21="전체","*",$G21)) | L21: =SUMIFS(매출원천!G:G,매출원천!$A:$A,$D21,매출원천!$B:$B,IF($G21="전체","*",$G21)) | M21: =SUMIFS(매출원천!H:H,매출원천!$A:$A,$D21,매출원천!$B:$B,IF($G21="전체","*",$G21)) | N21: =SUMIFS(매출원천!I:I,매출원천!$A:$A,$D21,매출원천!$B:$B,IF($G21="전체","*",$G21)) | O21: =SUMIFS(매출원천!J:J,매출원천!$A:$A,$D21,매출원천!$B:$B,IF($G21="전체","*",$G21)) | P21: =SUMIFS(매출원천!K:K,매출원천!$A:$A,$D21,매출원천!$B:$B,IF($G21="전체","*",$G21)) | Q21: =SUMIFS(매출원천!L:L,매출원천!$A:$A,$D21,매출원천!$B:$B,IF($G21="전체","*",$G21)) | R21: =COUNTIF(H21:Q21,">0") | S21: =IF($F21="",0,(YEAR($D$8)-YEAR($F21))*12+MONTH($D$8)-MONTH($F21)+1) | T21: =MAX(H21:Q21) | U21: =IF($Z21<>"",$Z21,IF($F21>=$D$6,"신상품",IF(AND($R21<=$D$7,$S21>$D$7),"스팟","기존"))) | V21: =IF($U21="신상품",IF($F21<=EOMONTH(V$9,0),$D$5,0),IF($U21="스팟",$Q21,$Q21*$D$4))*IF($AB21="",1,$AB21) | W21: =IF($U21="신상품",IF($F21<=EOMONTH(W$9,0),$D$5,0),IF($U21="스팟",0,IF($AA21="월평균",AVERAGEIF($H21:$P21,">0"),IF($AA21="9월",$P21,IF($AA21="10월",$V21,$T21)))))*IF($AC21="",1,$AC21) | X21: =IF($U21="신상품",IF($F21<=EOMONTH(X$9,0),$D$5,0),IF($U21="스팟",0,IF($AA21="월평균",AVERAGEIF($H21:$P21,">0"),IF($AA21="9월",$P21,IF($AA21="10월",$V21,$T21))))) | Y21: =SUM(H21:P21)+SUM(V21:X21)
A22: =신상품list!B14 | B22: =신상품list!C14 | C22: =신상품list!D14 | D22: =신상품list!E14&"" | E22: =신상품list!F14 | F22: =신상품list!H14 | G22: =IF(신상품list!I14="","전체",신상품list!I14) | H22: =SUMIFS(매출원천!C:C,매출원천!$A:$A,$D22,매출원천!$B:$B,IF($G22="전체","*",$G22)) | I22: =SUMIFS(매출원천!D:D,매출원천!$A:$A,$D22,매출원천!$B:$B,IF($G22="전체","*",$G22)) | J22: =SUMIFS(매출원천!E:E,매출원천!$A:$A,$D22,매출원천!$B:$B,IF($G22="전체","*",$G22)) | K22: =SUMIFS(매출원천!F:F,매출원천!$A:$A,$D22,매출원천!$B:$B,IF($G22="전체","*",$G22)) | L22: =SUMIFS(매출원천!G:G,매출원천!$A:$A,$D22,매출원천!$B:$B,IF($G22="전체","*",$G22)) | M22: =SUMIFS(매출원천!H:H,매출원천!$A:$A,$D22,매출원천!$B:$B,IF($G22="전체","*",$G22)) | N22: =SUMIFS(매출원천!I:I,매출원천!$A:$A,$D22,매출원천!$B:$B,IF($G22="전체","*",$G22)) | O22: =SUMIFS(매출원천!J:J,매출원천!$A:$A,$D22,매출원천!$B:$B,IF($G22="전체","*",$G22)) | P22: =SUMIFS(매출원천!K:K,매출원천!$A:$A,$D22,매출원천!$B:$B,IF($G22="전체","*",$G22)) | Q22: =SUMIFS(매출원천!L:L,매출원천!$A:$A,$D22,매출원천!$B:$B,IF($G22="전체","*",$G22)) | R22: =COUNTIF(H22:Q22,">0") | S22: =IF($F22="",0,(YEAR($D$8)-YEAR($F22))*12+MONTH($D$8)-MONTH($F22)+1) | T22: =MAX(H22:Q22) | U22: =IF($Z22<>"",$Z22,IF($F22>=$D$6,"신상품",IF(AND($R22<=$D$7,$S22>$D$7),"스팟","기존"))) | V22: =IF($U22="신상품",IF($F22<=EOMONTH(V$9,0),$D$5,0),IF($U22="스팟",$Q22,$Q22*$D$4))*IF($AB22="",1,$AB22) | W22: =IF($U22="신상품",IF($F22<=EOMONTH(W$9,0),$D$5,0),IF($U22="스팟",0,IF($AA22="월평균",AVERAGEIF($H22:$P22,">0"),IF($AA22="9월",$P22,IF($AA22="10월",$V22,$T22)))))*IF($AC22="",1,$AC22) | X22: =IF($U22="신상품",IF($F22<=EOMONTH(X$9,0),$D$5,0),IF($U22="스팟",0,IF($AA22="월평균",AVERAGEIF($H22:$P22,">0"),IF($AA22="9월",$P22,IF($AA22="10월",$V22,$T22))))) | Y22: =SUM(H22:P22)+SUM(V22:X22)
A23: =신상품list!B15 | B23: =신상품list!C15 | C23: =신상품list!D15 | D23: =신상품list!E15&"" | E23: =신상품list!F15 | F23: =신상품list!H15 | G23: =IF(신상품list!I15="","전체",신상품list!I15) | H23: =SUMIFS(매출원천!C:C,매출원천!$A:$A,$D23,매출원천!$B:$B,IF($G23="전체","*",$G23)) | I23: =SUMIFS(매출원천!D:D,매출원천!$A:$A,$D23,매출원천!$B:$B,IF($G23="전체","*",$G23)) | J23: =SUMIFS(매출원천!E:E,매출원천!$A:$A,$D23,매출원천!$B:$B,IF($G23="전체","*",$G23)) | K23: =SUMIFS(매출원천!F:F,매출원천!$A:$A,$D23,매출원천!$B:$B,IF($G23="전체","*",$G23)) | L23: =SUMIFS(매출원천!G:G,매출원천!$A:$A,$D23,매출원천!$B:$B,IF($G23="전체","*",$G23)) | M23: =SUMIFS(매출원천!H:H,매출원천!$A:$A,$D23,매출원천!$B:$B,IF($G23="전체","*",$G23)) | N23: =SUMIFS(매출원천!I:I,매출원천!$A:$A,$D23,매출원천!$B:$B,IF($G23="전체","*",$G23)) | O23: =SUMIFS(매출원천!J:J,매출원천!$A:$A,$D23,매출원천!$B:$B,IF($G23="전체","*",$G23)) | P23: =SUMIFS(매출원천!K:K,매출원천!$A:$A,$D23,매출원천!$B:$B,IF($G23="전체","*",$G23)) | Q23: =SUMIFS(매출원천!L:L,매출원천!$A:$A,$D23,매출원천!$B:$B,IF($G23="전체","*",$G23)) | R23: =COUNTIF(H23:Q23,">0") | S23: =IF($F23="",0,(YEAR($D$8)-YEAR($F23))*12+MONTH($D$8)-MONTH($F23)+1) | T23: =MAX(H23:Q23) | U23: =IF($Z23<>"",$Z23,IF($F23>=$D$6,"신상품",IF(AND($R23<=$D$7,$S23>$D$7),"스팟","기존"))) | V23: =IF($U23="신상품",IF($F23<=EOMONTH(V$9,0),$D$5,0),IF($U23="스팟",$Q23,$Q23*$D$4))*IF($AB23="",1,$AB23) | W23: =IF($U23="신상품",IF($F23<=EOMONTH(W$9,0),$D$5,0),IF($U23="스팟",0,IF($AA23="월평균",AVERAGEIF($H23:$P23,">0"),IF($AA23="9월",$P23,IF($AA23="10월",$V23,$T23)))))*IF($AC23="",1,$AC23) | X23: =IF($U23="신상품",IF($F23<=EOMONTH(X$9,0),$D$5,0),IF($U23="스팟",0,IF($AA23="월평균",AVERAGEIF($H23:$P23,">0"),IF($AA23="9월",$P23,IF($AA23="10월",$V23,$T23))))) | Y23: =SUM(H23:P23)+SUM(V23:X23)
A24: =신상품list!B16 | B24: =신상품list!C16 | C24: =신상품list!D16 | D24: =신상품list!E16&"" | E24: =신상품list!F16 | F24: =신상품list!H16 | G24: =IF(신상품list!I16="","전체",신상품list!I16) | H24: =SUMIFS(매출원천!C:C,매출원천!$A:$A,$D24,매출원천!$B:$B,IF($G24="전체","*",$G24)) | I24: =SUMIFS(매출원천!D:D,매출원천!$A:$A,$D24,매출원천!$B:$B,IF($G24="전체","*",$G24)) | J24: =SUMIFS(매출원천!E:E,매출원천!$A:$A,$D24,매출원천!$B:$B,IF($G24="전체","*",$G24)) | K24: =SUMIFS(매출원천!F:F,매출원천!$A:$A,$D24,매출원천!$B:$B,IF($G24="전체","*",$G24)) | L24: =SUMIFS(매출원천!G:G,매출원천!$A:$A,$D24,매출원천!$B:$B,IF($G24="전체","*",$G24)) | M24: =SUMIFS(매출원천!H:H,매출원천!$A:$A,$D24,매출원천!$B:$B,IF($G24="전체","*",$G24)) | N24: =SUMIFS(매출원천!I:I,매출원천!$A:$A,$D24,매출원천!$B:$B,IF($G24="전체","*",$G24)) | O24: =SUMIFS(매출원천!J:J,매출원천!$A:$A,$D24,매출원천!$B:$B,IF($G24="전체","*",$G24)) | P24: =SUMIFS(매출원천!K:K,매출원천!$A:$A,$D24,매출원천!$B:$B,IF($G24="전체","*",$G24)) | Q24: =SUMIFS(매출원천!L:L,매출원천!$A:$A,$D24,매출원천!$B:$B,IF($G24="전체","*",$G24)) | R24: =COUNTIF(H24:Q24,">0") | S24: =IF($F24="",0,(YEAR($D$8)-YEAR($F24))*12+MONTH($D$8)-MONTH($F24)+1) | T24: =MAX(H24:Q24) | U24: =IF($Z24<>"",$Z24,IF($F24>=$D$6,"신상품",IF(AND($R24<=$D$7,$S24>$D$7),"스팟","기존"))) | V24: =IF($U24="신상품",IF($F24<=EOMONTH(V$9,0),$D$5,0),IF($U24="스팟",$Q24,$Q24*$D$4))*IF($AB24="",1,$AB24) | W24: =IF($U24="신상품",IF($F24<=EOMONTH(W$9,0),$D$5,0),IF($U24="스팟",0,IF($AA24="월평균",AVERAGEIF($H24:$P24,">0"),IF($AA24="9월",$P24,IF($AA24="10월",$V24,$T24)))))*IF($AC24="",1,$AC24) | X24: =IF($U24="신상품",IF($F24<=EOMONTH(X$9,0),$D$5,0),IF($U24="스팟",0,IF($AA24="월평균",AVERAGEIF($H24:$P24,">0"),IF($AA24="9월",$P24,IF($AA24="10월",$V24,$T24))))) | Y24: =SUM(H24:P24)+SUM(V24:X24) | AA24: 10월
A25: =신상품list!B17 | B25: =신상품list!C17 | C25: =신상품list!D17 | D25: =신상품list!E17&"" | E25: =신상품list!F17 | F25: =신상품list!H17 | G25: =IF(신상품list!I17="","전체",신상품list!I17) | H25: =SUMIFS(매출원천!C:C,매출원천!$A:$A,$D25,매출원천!$B:$B,IF($G25="전체","*",$G25)) | I25: =SUMIFS(매출원천!D:D,매출원천!$A:$A,$D25,매출원천!$B:$B,IF($G25="전체","*",$G25)) | J25: =SUMIFS(매출원천!E:E,매출원천!$A:$A,$D25,매출원천!$B:$B,IF($G25="전체","*",$G25)) | K25: =SUMIFS(매출원천!F:F,매출원천!$A:$A,$D25,매출원천!$B:$B,IF($G25="전체","*",$G25)) | L25: =SUMIFS(매출원천!G:G,매출원천!$A:$A,$D25,매출원천!$B:$B,IF($G25="전체","*",$G25)) | M25: =SUMIFS(매출원천!H:H,매출원천!$A:$A,$D25,매출원천!$B:$B,IF($G25="전체","*",$G25)) | N25: =SUMIFS(매출원천!I:I,매출원천!$A:$A,$D25,매출원천!$B:$B,IF($G25="전체","*",$G25)) | O25: =SUMIFS(매출원천!J:J,매출원천!$A:$A,$D25,매출원천!$B:$B,IF($G25="전체","*",$G25)) | P25: =SUMIFS(매출원천!K:K,매출원천!$A:$A,$D25,매출원천!$B:$B,IF($G25="전체","*",$G25)) | Q25: =SUMIFS(매출원천!L:L,매출원천!$A:$A,$D25,매출원천!$B:$B,IF($G25="전체","*",$G25)) | R25: =COUNTIF(H25:Q25,">0") | S25: =IF($F25="",0,(YEAR($D$8)-YEAR($F25))*12+MONTH($D$8)-MONTH($F25)+1) | T25: =MAX(H25:Q25) | U25: =IF($Z25<>"",$Z25,IF($F25>=$D$6,"신상품",IF(AND($R25<=$D$7,$S25>$D$7),"스팟","기존"))) | V25: =IF($U25="신상품",IF($F25<=EOMONTH(V$9,0),$D$5,0),IF($U25="스팟",$Q25,$Q25*$D$4))*IF($AB25="",1,$AB25) | W25: =IF($U25="신상품",IF($F25<=EOMONTH(W$9,0),$D$5,0),IF($U25="스팟",0,IF($AA25="월평균",AVERAGEIF($H25:$P25,">0"),IF($AA25="9월",$P25,IF($AA25="10월",$V25,$T25)))))*IF($AC25="",1,$AC25) | X25: =IF($U25="신상품",IF($F25<=EOMONTH(X$9,0),$D$5,0),IF($U25="스팟",0,IF($AA25="월평균",AVERAGEIF($H25:$P25,">0"),IF($AA25="9월",$P25,IF($AA25="10월",$V25,$T25))))) | Y25: =SUM(H25:P25)+SUM(V25:X25)
A26: =신상품list!B18 | B26: =신상품list!C18 | C26: =신상품list!D18 | D26: =신상품list!E18&"" | E26: =신상품list!F18 | F26: =신상품list!H18 | G26: =IF(신상품list!I18="","전체",신상품list!I18) | H26: =SUMIFS(매출원천!C:C,매출원천!$A:$A,$D26,매출원천!$B:$B,IF($G26="전체","*",$G26)) | I26: =SUMIFS(매출원천!D:D,매출원천!$A:$A,$D26,매출원천!$B:$B,IF($G26="전체","*",$G26)) | J26: =SUMIFS(매출원천!E:E,매출원천!$A:$A,$D26,매출원천!$B:$B,IF($G26="전체","*",$G26)) | K26: =SUMIFS(매출원천!F:F,매출원천!$A:$A,$D26,매출원천!$B:$B,IF($G26="전체","*",$G26)) | L26: =SUMIFS(매출원천!G:G,매출원천!$A:$A,$D26,매출원천!$B:$B,IF($G26="전체","*",$G26)) | M26: =SUMIFS(매출원천!H:H,매출원천!$A:$A,$D26,매출원천!$B:$B,IF($G26="전체","*",$G26)) | N26: =SUMIFS(매출원천!I:I,매출원천!$A:$A,$D26,매출원천!$B:$B,IF($G26="전체","*",$G26)) | O26: =SUMIFS(매출원천!J:J,매출원천!$A:$A,$D26,매출원천!$B:$B,IF($G26="전체","*",$G26)) | P26: =SUMIFS(매출원천!K:K,매출원천!$A:$A,$D26,매출원천!$B:$B,IF($G26="전체","*",$G26)) | Q26: =SUMIFS(매출원천!L:L,매출원천!$A:$A,$D26,매출원천!$B:$B,IF($G26="전체","*",$G26)) | R26: =COUNTIF(H26:Q26,">0") | S26: =IF($F26="",0,(YEAR($D$8)-YEAR($F26))*12+MONTH($D$8)-MONTH($F26)+1) | T26: =MAX(H26:Q26) | U26: =IF($Z26<>"",$Z26,IF($F26>=$D$6,"신상품",IF(AND($R26<=$D$7,$S26>$D$7),"스팟","기존"))) | V26: =IF($U26="신상품",IF($F26<=EOMONTH(V$9,0),$D$5,0),IF($U26="스팟",$Q26,$Q26*$D$4))*IF($AB26="",1,$AB26) | W26: =IF($U26="신상품",IF($F26<=EOMONTH(W$9,0),$D$5,0),IF($U26="스팟",0,IF($AA26="월평균",AVERAGEIF($H26:$P26,">0"),IF($AA26="9월",$P26,IF($AA26="10월",$V26,$T26)))))*IF($AC26="",1,$AC26) | X26: =IF($U26="신상품",IF($F26<=EOMONTH(X$9,0),$D$5,0),IF($U26="스팟",0,IF($AA26="월평균",AVERAGEIF($H26:$P26,">0"),IF($AA26="9월",$P26,IF($AA26="10월",$V26,$T26))))) | Y26: =SUM(H26:P26)+SUM(V26:X26)
A27: =신상품list!B19 | B27: =신상품list!C19 | C27: =신상품list!D19 | D27: =신상품list!E19&"" | E27: =신상품list!F19 | F27: =신상품list!H19 | G27: =IF(신상품list!I19="","전체",신상품list!I19) | H27: =SUMIFS(매출원천!C:C,매출원천!$A:$A,$D27,매출원천!$B:$B,IF($G27="전체","*",$G27)) | I27: =SUMIFS(매출원천!D:D,매출원천!$A:$A,$D27,매출원천!$B:$B,IF($G27="전체","*",$G27)) | J27: =SUMIFS(매출원천!E:E,매출원천!$A:$A,$D27,매출원천!$B:$B,IF($G27="전체","*",$G27)) | K27: =SUMIFS(매출원천!F:F,매출원천!$A:$A,$D27,매출원천!$B:$B,IF($G27="전체","*",$G27)) | L27: =SUMIFS(매출원천!G:G,매출원천!$A:$A,$D27,매출원천!$B:$B,IF($G27="전체","*",$G27)) | M27: =SUMIFS(매출원천!H:H,매출원천!$A:$A,$D27,매출원천!$B:$B,IF($G27="전체","*",$G27)) | N27: =SUMIFS(매출원천!I:I,매출원천!$A:$A,$D27,매출원천!$B:$B,IF($G27="전체","*",$G27)) | O27: =SUMIFS(매출원천!J:J,매출원천!$A:$A,$D27,매출원천!$B:$B,IF($G27="전체","*",$G27)) | P27: =SUMIFS(매출원천!K:K,매출원천!$A:$A,$D27,매출원천!$B:$B,IF($G27="전체","*",$G27)) | Q27: =SUMIFS(매출원천!L:L,매출원천!$A:$A,$D27,매출원천!$B:$B,IF($G27="전체","*",$G27)) | R27: =COUNTIF(H27:Q27,">0") | S27: =IF($F27="",0,(YEAR($D$8)-YEAR($F27))*12+MONTH($D$8)-MONTH($F27)+1) | T27: =MAX(H27:Q27) | U27: =IF($Z27<>"",$Z27,IF($F27>=$D$6,"신상품",IF(AND($R27<=$D$7,$S27>$D$7),"스팟","기존"))) | V27: =IF($U27="신상품",IF($F27<=EOMONTH(V$9,0),$D$5,0),IF($U27="스팟",$Q27,$Q27*$D$4))*IF($AB27="",1,$AB27) | W27: =IF($U27="신상품",IF($F27<=EOMONTH(W$9,0),$D$5,0),IF($U27="스팟",0,IF($AA27="월평균",AVERAGEIF($H27:$P27,">0"),IF($AA27="9월",$P27,IF($AA27="10월",$V27,$T27)))))*IF($AC27="",1,$AC27) | X27: =IF($U27="신상품",IF($F27<=EOMONTH(X$9,0),$D$5,0),IF($U27="스팟",0,IF($AA27="월평균",AVERAGEIF($H27:$P27,">0"),IF($AA27="9월",$P27,IF($AA27="10월",$V27,$T27))))) | Y27: =SUM(H27:P27)+SUM(V27:X27)
A28: =신상품list!B20 | B28: =신상품list!C20 | C28: =신상품list!D20 | D28: =신상품list!E20&"" | E28: =신상품list!F20 | F28: =신상품list!H20 | G28: =IF(신상품list!I20="","전체",신상품list!I20) | H28: =SUMIFS(매출원천!C:C,매출원천!$A:$A,$D28,매출원천!$B:$B,IF($G28="전체","*",$G28)) | I28: =SUMIFS(매출원천!D:D,매출원천!$A:$A,$D28,매출원천!$B:$B,IF($G28="전체","*",$G28)) | J28: =SUMIFS(매출원천!E:E,매출원천!$A:$A,$D28,매출원천!$B:$B,IF($G28="전체","*",$G28)) | K28: =SUMIFS(매출원천!F:F,매출원천!$A:$A,$D28,매출원천!$B:$B,IF($G28="전체","*",$G28)) | L28: =SUMIFS(매출원천!G:G,매출원천!$A:$A,$D28,매출원천!$B:$B,IF($G28="전체","*",$G28)) | M28: =SUMIFS(매출원천!H:H,매출원천!$A:$A,$D28,매출원천!$B:$B,IF($G28="전체","*",$G28)) | N28: =SUMIFS(매출원천!I:I,매출원천!$A:$A,$D28,매출원천!$B:$B,IF($G28="전체","*",$G28)) | O28: =SUMIFS(매출원천!J:J,매출원천!$A:$A,$D28,매출원천!$B:$B,IF($G28="전체","*",$G28)) | P28: =SUMIFS(매출원천!K:K,매출원천!$A:$A,$D28,매출원천!$B:$B,IF($G28="전체","*",$G28)) | Q28: =SUMIFS(매출원천!L:L,매출원천!$A:$A,$D28,매출원천!$B:$B,IF($G28="전체","*",$G28)) | R28: =COUNTIF(H28:Q28,">0") | S28: =IF($F28="",0,(YEAR($D$8)-YEAR($F28))*12+MONTH($D$8)-MONTH($F28)+1) | T28: =MAX(H28:Q28) | U28: =IF($Z28<>"",$Z28,IF($F28>=$D$6,"신상품",IF(AND($R28<=$D$7,$S28>$D$7),"스팟","기존"))) | V28: =IF($U28="신상품",IF($F28<=EOMONTH(V$9,0),$D$5,0),IF($U28="스팟",$Q28,$Q28*$D$4))*IF($AB28="",1,$AB28) | W28: =IF($U28="신상품",IF($F28<=EOMONTH(W$9,0),$D$5,0),IF($U28="스팟",0,IF($AA28="월평균",AVERAGEIF($H28:$P28,">0"),IF($AA28="9월",$P28,IF($AA28="10월",$V28,$T28)))))*IF($AC28="",1,$AC28) | X28: =IF($U28="신상품",IF($F28<=EOMONTH(X$9,0),$D$5,0),IF($U28="스팟",0,IF($AA28="월평균",AVERAGEIF($H28:$P28,">0"),IF($AA28="9월",$P28,IF($AA28="10월",$V28,$T28))))) | Y28: =SUM(H28:P28)+SUM(V28:X28)
A29: =신상품list!B21 | B29: =신상품list!C21 | C29: =신상품list!D21 | D29: =신상품list!E21&"" | E29: =신상품list!F21 | F29: =신상품list!H21 | G29: =IF(신상품list!I21="","전체",신상품list!I21) | H29: =SUMIFS(매출원천!C:C,매출원천!$A:$A,$D29,매출원천!$B:$B,IF($G29="전체","*",$G29)) | I29: =SUMIFS(매출원천!D:D,매출원천!$A:$A,$D29,매출원천!$B:$B,IF($G29="전체","*",$G29)) | J29: =SUMIFS(매출원천!E:E,매출원천!$A:$A,$D29,매출원천!$B:$B,IF($G29="전체","*",$G29)) | K29: =SUMIFS(매출원천!F:F,매출원천!$A:$A,$D29,매출원천!$B:$B,IF($G29="전체","*",$G29)) | L29: =SUMIFS(매출원천!G:G,매출원천!$A:$A,$D29,매출원천!$B:$B,IF($G29="전체","*",$G29)) | M29: =SUMIFS(매출원천!H:H,매출원천!$A:$A,$D29,매출원천!$B:$B,IF($G29="전체","*",$G29)) | N29: =SUMIFS(매출원천!I:I,매출원천!$A:$A,$D29,매출원천!$B:$B,IF($G29="전체","*",$G29)) | O29: =SUMIFS(매출원천!J:J,매출원천!$A:$A,$D29,매출원천!$B:$B,IF($G29="전체","*",$G29)) | P29: =SUMIFS(매출원천!K:K,매출원천!$A:$A,$D29,매출원천!$B:$B,IF($G29="전체","*",$G29)) | Q29: =SUMIFS(매출원천!L:L,매출원천!$A:$A,$D29,매출원천!$B:$B,IF($G29="전체","*",$G29)) | R29: =COUNTIF(H29:Q29,">0") | S29: =IF($F29="",0,(YEAR($D$8)-YEAR($F29))*12+MONTH($D$8)-MONTH($F29)+1) | T29: =MAX(H29:Q29) | U29: =IF($Z29<>"",$Z29,IF($F29>=$D$6,"신상품",IF(AND($R29<=$D$7,$S29>$D$7),"스팟","기존"))) | V29: =IF($U29="신상품",IF($F29<=EOMONTH(V$9,0),$D$5,0),IF($U29="스팟",$Q29,$Q29*$D$4))*IF($AB29="",1,$AB29) | W29: =IF($U29="신상품",IF($F29<=EOMONTH(W$9,0),$D$5,0),IF($U29="스팟",0,IF($AA29="월평균",AVERAGEIF($H29:$P29,">0"),IF($AA29="9월",$P29,IF($AA29="10월",$V29,$T29)))))*IF($AC29="",1,$AC29) | X29: =IF($U29="신상품",IF($F29<=EOMONTH(X$9,0),$D$5,0),IF($U29="스팟",0,IF($AA29="월평균",AVERAGEIF($H29:$P29,">0"),IF($AA29="9월",$P29,IF($AA29="10월",$V29,$T29))))) | Y29: =SUM(H29:P29)+SUM(V29:X29)
A30: =신상품list!B22 | B30: =신상품list!C22 | C30: =신상품list!D22 | D30: =신상품list!E22&"" | E30: =신상품list!F22 | F30: =신상품list!H22 | G30: =IF(신상품list!I22="","전체",신상품list!I22) | H30: =SUMIFS(매출원천!C:C,매출원천!$A:$A,$D30,매출원천!$B:$B,IF($G30="전체","*",$G30)) | I30: =SUMIFS(매출원천!D:D,매출원천!$A:$A,$D30,매출원천!$B:$B,IF($G30="전체","*",$G30)) | J30: =SUMIFS(매출원천!E:E,매출원천!$A:$A,$D30,매출원천!$B:$B,IF($G30="전체","*",$G30)) | K30: =SUMIFS(매출원천!F:F,매출원천!$A:$A,$D30,매출원천!$B:$B,IF($G30="전체","*",$G30)) | L30: =SUMIFS(매출원천!G:G,매출원천!$A:$A,$D30,매출원천!$B:$B,IF($G30="전체","*",$G30)) | M30: =SUMIFS(매출원천!H:H,매출원천!$A:$A,$D30,매출원천!$B:$B,IF($G30="전체","*",$G30)) | N30: =SUMIFS(매출원천!I:I,매출원천!$A:$A,$D30,매출원천!$B:$B,IF($G30="전체","*",$G30)) | O30: =SUMIFS(매출원천!J:J,매출원천!$A:$A,$D30,매출원천!$B:$B,IF($G30="전체","*",$G30)) | P30: =SUMIFS(매출원천!K:K,매출원천!$A:$A,$D30,매출원천!$B:$B,IF($G30="전체","*",$G30)) | Q30: =SUMIFS(매출원천!L:L,매출원천!$A:$A,$D30,매출원천!$B:$B,IF($G30="전체","*",$G30)) | R30: =COUNTIF(H30:Q30,">0") | S30: =IF($F30="",0,(YEAR($D$8)-YEAR($F30))*12+MONTH($D$8)-MONTH($F30)+1) | T30: =MAX(H30:Q30) | U30: =IF($Z30<>"",$Z30,IF($F30>=$D$6,"신상품",IF(AND($R30<=$D$7,$S30>$D$7),"스팟","기존"))) | V30: =IF($U30="신상품",IF($F30<=EOMONTH(V$9,0),$D$5,0),IF($U30="스팟",$Q30,$Q30*$D$4))*IF($AB30="",1,$AB30) | W30: =IF($U30="신상품",IF($F30<=EOMONTH(W$9,0),$D$5,0),IF($U30="스팟",0,IF($AA30="월평균",AVERAGEIF($H30:$P30,">0"),IF($AA30="9월",$P30,IF($AA30="10월",$V30,$T30)))))*IF($AC30="",1,$AC30) | X30: =IF($U30="신상품",IF($F30<=EOMONTH(X$9,0),$D$5,0),IF($U30="스팟",0,IF($AA30="월평균",AVERAGEIF($H30:$P30,">0"),IF($AA30="9월",$P30,IF($AA30="10월",$V30,$T30))))) | Y30: =SUM(H30:P30)+SUM(V30:X30)
A31: =신상품list!B23 | B31: =신상품list!C23 | C31: =신상품list!D23 | D31: =신상품list!E23&"" | E31: =신상품list!F23 | F31: =신상품list!H23 | G31: =IF(신상품list!I23="","전체",신상품list!I23) | H31: =SUMIFS(매출원천!C:C,매출원천!$A:$A,$D31,매출원천!$B:$B,IF($G31="전체","*",$G31)) | I31: =SUMIFS(매출원천!D:D,매출원천!$A:$A,$D31,매출원천!$B:$B,IF($G31="전체","*",$G31)) | J31: =SUMIFS(매출원천!E:E,매출원천!$A:$A,$D31,매출원천!$B:$B,IF($G31="전체","*",$G31)) | K31: =SUMIFS(매출원천!F:F,매출원천!$A:$A,$D31,매출원천!$B:$B,IF($G31="전체","*",$G31)) | L31: =SUMIFS(매출원천!G:G,매출원천!$A:$A,$D31,매출원천!$B:$B,IF($G31="전체","*",$G31)) | M31: =SUMIFS(매출원천!H:H,매출원천!$A:$A,$D31,매출원천!$B:$B,IF($G31="전체","*",$G31)) | N31: =SUMIFS(매출원천!I:I,매출원천!$A:$A,$D31,매출원천!$B:$B,IF($G31="전체","*",$G31)) | O31: =SUMIFS(매출원천!J:J,매출원천!$A:$A,$D31,매출원천!$B:$B,IF($G31="전체","*",$G31)) | P31: =SUMIFS(매출원천!K:K,매출원천!$A:$A,$D31,매출원천!$B:$B,IF($G31="전체","*",$G31)) | Q31: =SUMIFS(매출원천!L:L,매출원천!$A:$A,$D31,매출원천!$B:$B,IF($G31="전체","*",$G31)) | R31: =COUNTIF(H31:Q31,">0") | S31: =IF($F31="",0,(YEAR($D$8)-YEAR($F31))*12+MONTH($D$8)-MONTH($F31)+1) | T31: =MAX(H31:Q31) | U31: =IF($Z31<>"",$Z31,IF($F31>=$D$6,"신상품",IF(AND($R31<=$D$7,$S31>$D$7),"스팟","기존"))) | V31: =IF($U31="신상품",IF($F31<=EOMONTH(V$9,0),$D$5,0),IF($U31="스팟",$Q31,$Q31*$D$4))*IF($AB31="",1,$AB31) | W31: =IF($U31="신상품",IF($F31<=EOMONTH(W$9,0),$D$5,0),IF($U31="스팟",0,IF($AA31="월평균",AVERAGEIF($H31:$P31,">0"),IF($AA31="9월",$P31,IF($AA31="10월",$V31,$T31)))))*IF($AC31="",1,$AC31) | X31: =IF($U31="신상품",IF($F31<=EOMONTH(X$9,0),$D$5,0),IF($U31="스팟",0,IF($AA31="월평균",AVERAGEIF($H31:$P31,">0"),IF($AA31="9월",$P31,IF($AA31="10월",$V31,$T31))))) | Y31: =SUM(H31:P31)+SUM(V31:X31)
A32: =신상품list!B24 | B32: =신상품list!C24 | C32: =신상품list!D24 | D32: =신상품list!E24&"" | E32: =신상품list!F24 | F32: =신상품list!H24 | G32: =IF(신상품list!I24="","전체",신상품list!I24) | H32: =SUMIFS(매출원천!C:C,매출원천!$A:$A,$D32,매출원천!$B:$B,IF($G32="전체","*",$G32)) | I32: =SUMIFS(매출원천!D:D,매출원천!$A:$A,$D32,매출원천!$B:$B,IF($G32="전체","*",$G32)) | J32: =SUMIFS(매출원천!E:E,매출원천!$A:$A,$D32,매출원천!$B:$B,IF($G32="전체","*",$G32)) | K32: =SUMIFS(매출원천!F:F,매출원천!$A:$A,$D32,매출원천!$B:$B,IF($G32="전체","*",$G32)) | L32: =SUMIFS(매출원천!G:G,매출원천!$A:$A,$D32,매출원천!$B:$B,IF($G32="전체","*",$G32)) | M32: =SUMIFS(매출원천!H:H,매출원천!$A:$A,$D32,매출원천!$B:$B,IF($G32="전체","*",$G32)) | N32: =SUMIFS(매출원천!I:I,매출원천!$A:$A,$D32,매출원천!$B:$B,IF($G32="전체","*",$G32)) | O32: =SUMIFS(매출원천!J:J,매출원천!$A:$A,$D32,매출원천!$B:$B,IF($G32="전체","*",$G32)) | P32: =SUMIFS(매출원천!K:K,매출원천!$A:$A,$D32,매출원천!$B:$B,IF($G32="전체","*",$G32)) | Q32: =SUMIFS(매출원천!L:L,매출원천!$A:$A,$D32,매출원천!$B:$B,IF($G32="전체","*",$G32)) | R32: =COUNTIF(H32:Q32,">0") | S32: =IF($F32="",0,(YEAR($D$8)-YEAR($F32))*12+MONTH($D$8)-MONTH($F32)+1) | T32: =MAX(H32:Q32) | U32: =IF($Z32<>"",$Z32,IF($F32>=$D$6,"신상품",IF(AND($R32<=$D$7,$S32>$D$7),"스팟","기존"))) | V32: =IF($U32="신상품",IF($F32<=EOMONTH(V$9,0),$D$5,0),IF($U32="스팟",$Q32,$Q32*$D$4))*IF($AB32="",1,$AB32) | W32: =IF($U32="신상품",IF($F32<=EOMONTH(W$9,0),$D$5,0),IF($U32="스팟",0,IF($AA32="월평균",AVERAGEIF($H32:$P32,">0"),IF($AA32="9월",$P32,IF($AA32="10월",$V32,$T32)))))*IF($AC32="",1,$AC32) | X32: =IF($U32="신상품",IF($F32<=EOMONTH(X$9,0),$D$5,0),IF($U32="스팟",0,IF($AA32="월평균",AVERAGEIF($H32:$P32,">0"),IF($AA32="9월",$P32,IF($AA32="10월",$V32,$T32))))) | Y32: =SUM(H32:P32)+SUM(V32:X32)
A33: =신상품list!B25 | B33: =신상품list!C25 | C33: =신상품list!D25 | D33: =신상품list!E25&"" | E33: =신상품list!F25 | F33: =신상품list!H25 | G33: =IF(신상품list!I25="","전체",신상품list!I25) | H33: =SUMIFS(매출원천!C:C,매출원천!$A:$A,$D33,매출원천!$B:$B,IF($G33="전체","*",$G33)) | I33: =SUMIFS(매출원천!D:D,매출원천!$A:$A,$D33,매출원천!$B:$B,IF($G33="전체","*",$G33)) | J33: =SUMIFS(매출원천!E:E,매출원천!$A:$A,$D33,매출원천!$B:$B,IF($G33="전체","*",$G33)) | K33: =SUMIFS(매출원천!F:F,매출원천!$A:$A,$D33,매출원천!$B:$B,IF($G33="전체","*",$G33)) | L33: =SUMIFS(매출원천!G:G,매출원천!$A:$A,$D33,매출원천!$B:$B,IF($G33="전체","*",$G33)) | M33: =SUMIFS(매출원천!H:H,매출원천!$A:$A,$D33,매출원천!$B:$B,IF($G33="전체","*",$G33)) | N33: =SUMIFS(매출원천!I:I,매출원천!$A:$A,$D33,매출원천!$B:$B,IF($G33="전체","*",$G33)) | O33: =SUMIFS(매출원천!J:J,매출원천!$A:$A,$D33,매출원천!$B:$B,IF($G33="전체","*",$G33)) | P33: =SUMIFS(매출원천!K:K,매출원천!$A:$A,$D33,매출원천!$B:$B,IF($G33="전체","*",$G33)) | Q33: =SUMIFS(매출원천!L:L,매출원천!$A:$A,$D33,매출원천!$B:$B,IF($G33="전체","*",$G33)) | R33: =COUNTIF(H33:Q33,">0") | S33: =IF($F33="",0,(YEAR($D$8)-YEAR($F33))*12+MONTH($D$8)-MONTH($F33)+1) | T33: =MAX(H33:Q33) | U33: =IF($Z33<>"",$Z33,IF($F33>=$D$6,"신상품",IF(AND($R33<=$D$7,$S33>$D$7),"스팟","기존"))) | V33: =IF($U33="신상품",IF($F33<=EOMONTH(V$9,0),$D$5,0),IF($U33="스팟",$Q33,$Q33*$D$4))*IF($AB33="",1,$AB33) | W33: =IF($U33="신상품",IF($F33<=EOMONTH(W$9,0),$D$5,0),IF($U33="스팟",0,IF($AA33="월평균",AVERAGEIF($H33:$P33,">0"),IF($AA33="9월",$P33,IF($AA33="10월",$V33,$T33)))))*IF($AC33="",1,$AC33) | X33: =IF($U33="신상품",IF($F33<=EOMONTH(X$9,0),$D$5,0),IF($U33="스팟",0,IF($AA33="월평균",AVERAGEIF($H33:$P33,">0"),IF($AA33="9월",$P33,IF($AA33="10월",$V33,$T33))))) | Y33: =SUM(H33:P33)+SUM(V33:X33)
A34: =신상품list!B26 | B34: =신상품list!C26 | C34: =신상품list!D26 | D34: =신상품list!E26&"" | E34: =신상품list!F26 | F34: =신상품list!H26 | G34: =IF(신상품list!I26="","전체",신상품list!I26) | H34: =SUMIFS(매출원천!C:C,매출원천!$A:$A,$D34,매출원천!$B:$B,IF($G34="전체","*",$G34)) | I34: =SUMIFS(매출원천!D:D,매출원천!$A:$A,$D34,매출원천!$B:$B,IF($G34="전체","*",$G34)) | J34: =SUMIFS(매출원천!E:E,매출원천!$A:$A,$D34,매출원천!$B:$B,IF($G34="전체","*",$G34)) | K34: =SUMIFS(매출원천!F:F,매출원천!$A:$A,$D34,매출원천!$B:$B,IF($G34="전체","*",$G34)) | L34: =SUMIFS(매출원천!G:G,매출원천!$A:$A,$D34,매출원천!$B:$B,IF($G34="전체","*",$G34)) | M34: =SUMIFS(매출원천!H:H,매출원천!$A:$A,$D34,매출원천!$B:$B,IF($G34="전체","*",$G34)) | N34: =SUMIFS(매출원천!I:I,매출원천!$A:$A,$D34,매출원천!$B:$B,IF($G34="전체","*",$G34)) | O34: =SUMIFS(매출원천!J:J,매출원천!$A:$A,$D34,매출원천!$B:$B,IF($G34="전체","*",$G34)) | P34: =SUMIFS(매출원천!K:K,매출원천!$A:$A,$D34,매출원천!$B:$B,IF($G34="전체","*",$G34)) | Q34: =SUMIFS(매출원천!L:L,매출원천!$A:$A,$D34,매출원천!$B:$B,IF($G34="전체","*",$G34)) | R34: =COUNTIF(H34:Q34,">0") | S34: =IF($F34="",0,(YEAR($D$8)-YEAR($F34))*12+MONTH($D$8)-MONTH($F34)+1) | T34: =MAX(H34:Q34) | U34: =IF($Z34<>"",$Z34,IF($F34>=$D$6,"신상품",IF(AND($R34<=$D$7,$S34>$D$7),"스팟","기존"))) | V34: =IF($U34="신상품",IF($F34<=EOMONTH(V$9,0),$D$5,0),IF($U34="스팟",$Q34,$Q34*$D$4))*IF($AB34="",1,$AB34) | W34: =IF($U34="신상품",IF($F34<=EOMONTH(W$9,0),$D$5,0),IF($U34="스팟",0,IF($AA34="월평균",AVERAGEIF($H34:$P34,">0"),IF($AA34="9월",$P34,IF($AA34="10월",$V34,$T34)))))*IF($AC34="",1,$AC34) | X34: =IF($U34="신상품",IF($F34<=EOMONTH(X$9,0),$D$5,0),IF($U34="스팟",0,IF($AA34="월평균",AVERAGEIF($H34:$P34,">0"),IF($AA34="9월",$P34,IF($AA34="10월",$V34,$T34))))) | Y34: =SUM(H34:P34)+SUM(V34:X34)
A35: =신상품list!B27 | B35: =신상품list!C27 | C35: =신상품list!D27 | D35: =신상품list!E27&"" | E35: =신상품list!F27 | F35: =신상품list!H27 | G35: =IF(신상품list!I27="","전체",신상품list!I27) | H35: =SUMIFS(매출원천!C:C,매출원천!$A:$A,$D35,매출원천!$B:$B,IF($G35="전체","*",$G35)) | I35: =SUMIFS(매출원천!D:D,매출원천!$A:$A,$D35,매출원천!$B:$B,IF($G35="전체","*",$G35)) | J35: =SUMIFS(매출원천!E:E,매출원천!$A:$A,$D35,매출원천!$B:$B,IF($G35="전체","*",$G35)) | K35: =SUMIFS(매출원천!F:F,매출원천!$A:$A,$D35,매출원천!$B:$B,IF($G35="전체","*",$G35)) | L35: =SUMIFS(매출원천!G:G,매출원천!$A:$A,$D35,매출원천!$B:$B,IF($G35="전체","*",$G35)) | M35: =SUMIFS(매출원천!H:H,매출원천!$A:$A,$D35,매출원천!$B:$B,IF($G35="전체","*",$G35)) | N35: =SUMIFS(매출원천!I:I,매출원천!$A:$A,$D35,매출원천!$B:$B,IF($G35="전체","*",$G35)) | O35: =SUMIFS(매출원천!J:J,매출원천!$A:$A,$D35,매출원천!$B:$B,IF($G35="전체","*",$G35)) | P35: =SUMIFS(매출원천!K:K,매출원천!$A:$A,$D35,매출원천!$B:$B,IF($G35="전체","*",$G35)) | Q35: =SUMIFS(매출원천!L:L,매출원천!$A:$A,$D35,매출원천!$B:$B,IF($G35="전체","*",$G35)) | R35: =COUNTIF(H35:Q35,">0") | S35: =IF($F35="",0,(YEAR($D$8)-YEAR($F35))*12+MONTH($D$8)-MONTH($F35)+1) | T35: =MAX(H35:Q35) | U35: =IF($Z35<>"",$Z35,IF($F35>=$D$6,"신상품",IF(AND($R35<=$D$7,$S35>$D$7),"스팟","기존"))) | V35: =IF($U35="신상품",IF($F35<=EOMONTH(V$9,0),$D$5,0),IF($U35="스팟",$Q35,$Q35*$D$4))*IF($AB35="",1,$AB35) | W35: =IF($U35="신상품",IF($F35<=EOMONTH(W$9,0),$D$5,0),IF($U35="스팟",0,IF($AA35="월평균",AVERAGEIF($H35:$P35,">0"),IF($AA35="9월",$P35,IF($AA35="10월",$V35,$T35)))))*IF($AC35="",1,$AC35) | X35: =IF($U35="신상품",IF($F35<=EOMONTH(X$9,0),$D$5,0),IF($U35="스팟",0,IF($AA35="월평균",AVERAGEIF($H35:$P35,">0"),IF($AA35="9월",$P35,IF($AA35="10월",$V35,$T35))))) | Y35: =SUM(H35:P35)+SUM(V35:X35)
A36: =신상품list!B28 | B36: =신상품list!C28 | C36: =신상품list!D28 | D36: =신상품list!E28&"" | E36: =신상품list!F28 | F36: =신상품list!H28 | G36: =IF(신상품list!I28="","전체",신상품list!I28) | H36: =SUMIFS(매출원천!C:C,매출원천!$A:$A,$D36,매출원천!$B:$B,IF($G36="전체","*",$G36)) | I36: =SUMIFS(매출원천!D:D,매출원천!$A:$A,$D36,매출원천!$B:$B,IF($G36="전체","*",$G36)) | J36: =SUMIFS(매출원천!E:E,매출원천!$A:$A,$D36,매출원천!$B:$B,IF($G36="전체","*",$G36)) | K36: =SUMIFS(매출원천!F:F,매출원천!$A:$A,$D36,매출원천!$B:$B,IF($G36="전체","*",$G36)) | L36: =SUMIFS(매출원천!G:G,매출원천!$A:$A,$D36,매출원천!$B:$B,IF($G36="전체","*",$G36)) | M36: =SUMIFS(매출원천!H:H,매출원천!$A:$A,$D36,매출원천!$B:$B,IF($G36="전체","*",$G36)) | N36: =SUMIFS(매출원천!I:I,매출원천!$A:$A,$D36,매출원천!$B:$B,IF($G36="전체","*",$G36)) | O36: =SUMIFS(매출원천!J:J,매출원천!$A:$A,$D36,매출원천!$B:$B,IF($G36="전체","*",$G36)) | P36: =SUMIFS(매출원천!K:K,매출원천!$A:$A,$D36,매출원천!$B:$B,IF($G36="전체","*",$G36)) | Q36: =SUMIFS(매출원천!L:L,매출원천!$A:$A,$D36,매출원천!$B:$B,IF($G36="전체","*",$G36)) | R36: =COUNTIF(H36:Q36,">0") | S36: =IF($F36="",0,(YEAR($D$8)-YEAR($F36))*12+MONTH($D$8)-MONTH($F36)+1) | T36: =MAX(H36:Q36) | U36: =IF($Z36<>"",$Z36,IF($F36>=$D$6,"신상품",IF(AND($R36<=$D$7,$S36>$D$7),"스팟","기존"))) | V36: =IF($U36="신상품",IF($F36<=EOMONTH(V$9,0),$D$5,0),IF($U36="스팟",$Q36,$Q36*$D$4))*IF($AB36="",1,$AB36) | W36: =IF($U36="신상품",IF($F36<=EOMONTH(W$9,0),$D$5,0),IF($U36="스팟",0,IF($AA36="월평균",AVERAGEIF($H36:$P36,">0"),IF($AA36="9월",$P36,IF($AA36="10월",$V36,$T36)))))*IF($AC36="",1,$AC36) | X36: =IF($U36="신상품",IF($F36<=EOMONTH(X$9,0),$D$5,0),IF($U36="스팟",0,IF($AA36="월평균",AVERAGEIF($H36:$P36,">0"),IF($AA36="9월",$P36,IF($AA36="10월",$V36,$T36))))) | Y36: =SUM(H36:P36)+SUM(V36:X36)
... A45: =신상품list!B37 | B45: =신상품list!C37 | C45: =신상품list!D37 | D45: =신상품list!E37&"" | E45: =신상품list!F37 | F45: =신상품list!H37 | G45: =IF(신상품list!I37="","전체",신상품list!I37) | H45: =SUMIFS(매출원천!C:C,매출원천!$A:$A,$D45,매출원천!$B:$B,IF($G45="전체","*",$G45)) | I45: =SUMIFS(매출원천!D:D,매출원천!$A:$A,$D45,매출원천!$B:$B,IF($G45="전체","*",$G45)) | J45: =SUMIFS(매출원천!E:E,매출원천!$A:$A,$D45,매출원천!$B:$B,IF($G45="전체","*",$G45)) | K45: =SUMIFS(매출원천!F:F,매출원천!$A:$A,$D45,매출원천!$B:$B,IF($G45="전체","*",$G45)) | L45: =SUMIFS(매출원천!G:G,매출원천!$A:$A,$D45,매출원천!$B:$B,IF($G45="전체","*",$G45)) | M45: =SUMIFS(매출원천!H:H,매출원천!$A:$A,$D45,매출원천!$B:$B,IF($G45="전체","*",$G45)) | N45: =SUMIFS(매출원천!I:I,매출원천!$A:$A,$D45,매출원천!$B:$B,IF($G45="전체","*",$G45)) | O45: =SUMIFS(매출원천!J:J,매출원천!$A:$A,$D45,매출원천!$B:$B,IF($G45="전체","*",$G45)) | P45: =SUMIFS(매출원천!K:K,매출원천!$A:$A,$D45,매출원천!$B:$B,IF($G45="전체","*",$G45)) | Q45: =SUMIFS(매출원천!L:L,매출원천!$A:$A,$D45,매출원천!$B:$B,IF($G45="전체","*",$G45)) | R45: =COUNTIF(H45:Q45,">0") | S45: =IF($F45="",0,(YEAR($D$8)-YEAR($F45))*12+MONTH($D$8)-MONTH($F45)+1) | T45: =MAX(H45:Q45) | U45: =IF($Z45<>"",$Z45,IF($F45>=$D$6,"신상품",IF(AND($R45<=$D$7,$S45>$D$7),"스팟","기존"))) | V45: =IF($U45="신상품",IF($F45<=EOMONTH(V$9,0),$D$5,0),IF($U45="스팟",$Q45,$Q45*$D$4))*IF($AB45="",1,$AB45) | W45: =IF($U45="신상품",IF($F45<=EOMONTH(W$9,0),$D$5,0),IF($U45="스팟",0,IF($AA45="월평균",AVERAGEIF($H45:$P45,">0"),IF($AA45="9월",$P45,IF($AA45="10월",$V45,$T45)))))*IF($AC45="",1,$AC45) | X45: =IF($U45="신상품",IF($F45<=EOMONTH(X$9,0),$D$5,0),IF($U45="스팟",0,IF($AA45="월평균",AVERAGEIF($H45:$P45,">0"),IF($AA45="9월",$P45,IF($AA45="10월",$V45,$T45))))) | Y45: =SUM(H45:P45)+SUM(V45:X45)
A46: =신상품list!B38 | B46: =신상품list!C38 | C46: =신상품list!D38 | D46: =신상품list!E38&"" | E46: =신상품list!F38 | F46: =신상품list!H38 | G46: =IF(신상품list!I38="","전체",신상품list!I38) | H46: =SUMIFS(매출원천!C:C,매출원천!$A:$A,$D46,매출원천!$B:$B,IF($G46="전체","*",$G46)) | I46: =SUMIFS(매출원천!D:D,매출원천!$A:$A,$D46,매출원천!$B:$B,IF($G46="전체","*",$G46)) | J46: =SUMIFS(매출원천!E:E,매출원천!$A:$A,$D46,매출원천!$B:$B,IF($G46="전체","*",$G46)) | K46: =SUMIFS(매출원천!F:F,매출원천!$A:$A,$D46,매출원천!$B:$B,IF($G46="전체","*",$G46)) | L46: =SUMIFS(매출원천!G:G,매출원천!$A:$A,$D46,매출원천!$B:$B,IF($G46="전체","*",$G46)) | M46: =SUMIFS(매출원천!H:H,매출원천!$A:$A,$D46,매출원천!$B:$B,IF($G46="전체","*",$G46)) | N46: =SUMIFS(매출원천!I:I,매출원천!$A:$A,$D46,매출원천!$B:$B,IF($G46="전체","*",$G46)) | O46: =SUMIFS(매출원천!J:J,매출원천!$A:$A,$D46,매출원천!$B:$B,IF($G46="전체","*",$G46)) | P46: =SUMIFS(매출원천!K:K,매출원천!$A:$A,$D46,매출원천!$B:$B,IF($G46="전체","*",$G46)) | Q46: =SUMIFS(매출원천!L:L,매출원천!$A:$A,$D46,매출원천!$B:$B,IF($G46="전체","*",$G46)) | R46: =COUNTIF(H46:Q46,">0") | S46: =IF($F46="",0,(YEAR($D$8)-YEAR($F46))*12+MONTH($D$8)-MONTH($F46)+1) | T46: =MAX(H46:Q46) | U46: =IF($Z46<>"",$Z46,IF($F46>=$D$6,"신상품",IF(AND($R46<=$D$7,$S46>$D$7),"스팟","기존"))) | V46: =IF($U46="신상품",IF($F46<=EOMONTH(V$9,0),$D$5,0),IF($U46="스팟",$Q46,$Q46*$D$4))*IF($AB46="",1,$AB46) | W46: =IF($U46="신상품",IF($F46<=EOMONTH(W$9,0),$D$5,0),IF($U46="스팟",0,IF($AA46="월평균",AVERAGEIF($H46:$P46,">0"),IF($AA46="9월",$P46,IF($AA46="10월",$V46,$T46)))))*IF($AC46="",1,$AC46) | X46: =IF($U46="신상품",IF($F46<=EOMONTH(X$9,0),$D$5,0),IF($U46="스팟",0,IF($AA46="월평균",AVERAGEIF($H46:$P46,">0"),IF($AA46="9월",$P46,IF($AA46="10월",$V46,$T46))))) | Y46: =SUM(H46:P46)+SUM(V46:X46) | AB46: 0
A47: =신상품list!B39 | B47: =신상품list!C39 | C47: =신상품list!D39 | D47: =신상품list!E39&"" | E47: =신상품list!F39 | F47: =신상품list!H39 | G47: =IF(신상품list!I39="","전체",신상품list!I39) | H47: =SUMIFS(매출원천!C:C,매출원천!$A:$A,$D47,매출원천!$B:$B,IF($G47="전체","*",$G47)) | I47: =SUMIFS(매출원천!D:D,매출원천!$A:$A,$D47,매출원천!$B:$B,IF($G47="전체","*",$G47)) | J47: =SUMIFS(매출원천!E:E,매출원천!$A:$A,$D47,매출원천!$B:$B,IF($G47="전체","*",$G47)) | K47: =SUMIFS(매출원천!F:F,매출원천!$A:$A,$D47,매출원천!$B:$B,IF($G47="전체","*",$G47)) | L47: =SUMIFS(매출원천!G:G,매출원천!$A:$A,$D47,매출원천!$B:$B,IF($G47="전체","*",$G47)) | M47: =SUMIFS(매출원천!H:H,매출원천!$A:$A,$D47,매출원천!$B:$B,IF($G47="전체","*",$G47)) | N47: =SUMIFS(매출원천!I:I,매출원천!$A:$A,$D47,매출원천!$B:$B,IF($G47="전체","*",$G47)) | O47: =SUMIFS(매출원천!J:J,매출원천!$A:$A,$D47,매출원천!$B:$B,IF($G47="전체","*",$G47)) | P47: =SUMIFS(매출원천!K:K,매출원천!$A:$A,$D47,매출원천!$B:$B,IF($G47="전체","*",$G47)) | Q47: =SUMIFS(매출원천!L:L,매출원천!$A:$A,$D47,매출원천!$B:$B,IF($G47="전체","*",$G47)) | R47: =COUNTIF(H47:Q47,">0") | S47: =IF($F47="",0,(YEAR($D$8)-YEAR($F47))*12+MONTH($D$8)-MONTH($F47)+1) | T47: =MAX(H47:Q47) | U47: =IF($Z47<>"",$Z47,IF($F47>=$D$6,"신상품",IF(AND($R47<=$D$7,$S47>$D$7),"스팟","기존"))) | V47: =IF($U47="신상품",IF($F47<=EOMONTH(V$9,0),$D$5,0),IF($U47="스팟",$Q47,$Q47*$D$4))*IF($AB47="",1,$AB47) | W47: =IF($U47="신상품",IF($F47<=EOMONTH(W$9,0),$D$5,0),IF($U47="스팟",0,IF($AA47="월평균",AVERAGEIF($H47:$P47,">0"),IF($AA47="9월",$P47,IF($AA47="10월",$V47,$T47)))))*IF($AC47="",1,$AC47) | X47: =IF($U47="신상품",IF($F47<=EOMONTH(X$9,0),$D$5,0),IF($U47="스팟",0,IF($AA47="월평균",AVERAGEIF($H47:$P47,">0"),IF($AA47="9월",$P47,IF($AA47="10월",$V47,$T47))))) | Y47: =SUM(H47:P47)+SUM(V47:X47) | AB47: 0
A48: =신상품list!B40 | B48: =신상품list!C40 | C48: =신상품list!D40 | D48: =신상품list!E40&"" | E48: =신상품list!F40 | F48: =신상품list!H40 | G48: =IF(신상품list!I40="","전체",신상품list!I40) | H48: =SUMIFS(매출원천!C:C,매출원천!$A:$A,$D48,매출원천!$B:$B,IF($G48="전체","*",$G48)) | I48: =SUMIFS(매출원천!D:D,매출원천!$A:$A,$D48,매출원천!$B:$B,IF($G48="전체","*",$G48)) | J48: =SUMIFS(매출원천!E:E,매출원천!$A:$A,$D48,매출원천!$B:$B,IF($G48="전체","*",$G48)) | K48: =SUMIFS(매출원천!F:F,매출원천!$A:$A,$D48,매출원천!$B:$B,IF($G48="전체","*",$G48)) | L48: =SUMIFS(매출원천!G:G,매출원천!$A:$A,$D48,매출원천!$B:$B,IF($G48="전체","*",$G48)) | M48: =SUMIFS(매출원천!H:H,매출원천!$A:$A,$D48,매출원천!$B:$B,IF($G48="전체","*",$G48)) | N48: =SUMIFS(매출원천!I:I,매출원천!$A:$A,$D48,매출원천!$B:$B,IF($G48="전체","*",$G48)) | O48: =SUMIFS(매출원천!J:J,매출원천!$A:$A,$D48,매출원천!$B:$B,IF($G48="전체","*",$G48)) | P48: =SUMIFS(매출원천!K:K,매출원천!$A:$A,$D48,매출원천!$B:$B,IF($G48="전체","*",$G48)) | Q48: =SUMIFS(매출원천!L:L,매출원천!$A:$A,$D48,매출원천!$B:$B,IF($G48="전체","*",$G48)) | R48: =COUNTIF(H48:Q48,">0") | S48: =IF($F48="",0,(YEAR($D$8)-YEAR($F48))*12+MONTH($D$8)-MONTH($F48)+1) | T48: =MAX(H48:Q48) | U48: =IF($Z48<>"",$Z48,IF($F48>=$D$6,"신상품",IF(AND($R48<=$D$7,$S48>$D$7),"스팟","기존"))) | V48: =IF($U48="신상품",IF($F48<=EOMONTH(V$9,0),$D$5,0),IF($U48="스팟",$Q48,$Q48*$D$4))*IF($AB48="",1,$AB48) | W48: =IF($U48="신상품",IF($F48<=EOMONTH(W$9,0),$D$5,0),IF($U48="스팟",0,IF($AA48="월평균",AVERAGEIF($H48:$P48,">0"),IF($AA48="9월",$P48,IF($AA48="10월",$V48,$T48)))))*IF($AC48="",1,$AC48) | X48: =IF($U48="신상품",IF($F48<=EOMONTH(X$9,0),$D$5,0),IF($U48="스팟",0,IF($AA48="월평균",AVERAGEIF($H48:$P48,">0"),IF($AA48="9월",$P48,IF($AA48="10월",$V48,$T48))))) | Y48: =SUM(H48:P48)+SUM(V48:X48) | AB48: 0
...
